Workbook

Sheet Overall Bean Summary
A1: Flavor | B1: Good/Bad | C1: Seasons | D1: Bean | E1: Total | F1: % | I1: Good | K1: Bad | M1: Spicy | N1: Total | O1: /day | P1: /weekday | Q1: /week | R1: First Bean | S1: Last Bean
A2: Juicy Pear | B2: Good | C2: 1st-Curr | D2: =D3 | E2: =COUNTIFS(Beans!B:B, A2) -> 18 | F2: =IF(E2+E3 = 0, "n/a", E2/(E2+E3)) -> 0.140625 | H2: 2022 | I2: ='2022 Bean Description'!B35 -> 20 | J2: =I2/(I2+K2) -> 0.3125 | K2: ='2022 Bean Description'!B36 -> 44 | L2: =K2/(I2+K2) -> 0.6875 | M2: ='2022 Bean Description'!B37 -> 5 | N2: =I2+K2+M2 -> 69 | O2: =N2/(S2-R2+1) -> 0.92 | P2: =N2/(((S2-R2+1)/7)*5) -> 1.288 | Q2: =N2/(((S2-R2+1)/7)) -> 6.44 | R2: =Beans!A2 -> 44852 | S2: 44926
A3: Booger | B3: Bad | C3: 1st-Curr | E3: =COUNTIFS(Beans!B:B, A3) -> 110 | F3: =IF(E2+E3 = 0, "n/a", E3/(E2+E3)) -> 0.859375 | H3: 2023 | I3: ='2023 Bean Description'!B35 -> 148 | J3: ='2023 Summary'!B77 -> 0.27205882 | K3: ='2023 Bean Description'!B36 -> 396 | L3: ='2023 Summary'!C77 -> 0.72794118 | M3: ='2023 Bean Description'!B37 -> 25 | N3: =I3+K3+M3 -> 569 | O3: =N3/(S3-R3+1) -> 1.5589041 | P3: =N3/(((S3-R3+1)/7)*5) -> 2.1824658 | Q3: =N3/(((S3-R3+1)/7)) -> 10.912329 | R3: 44927 | S3: 45291
A4: Strawberry Smoothie | B4: Good | C4: 4th-Curr | D4: =D5 | E4: =COUNTIFS(Beans!B:B, A4) -> 41 | F4: =IF(E4+E5 = 0, "n/a", E4/(E4+E5)) -> 0.31782946 | H4: 2024 | I4: ='2024 Bean Description'!B39 -> 83 | J4: ='2024 Summary'!B77 -> 0.22739726 | K4: ='2024 Bean Description'!B40 -> 282 | L4: ='2024 Summary'!C77 -> 0.77260274 | M4: ='2024 Bean Description'!B41 -> 0 | N4: =I4+K4+M4 -> 365 | O4: =N4/(S4-R4+1) -> 0.99726776 | P4: =N4/(((S4-R4+1)/7)*5) -> 1.3961749 | Q4: =N4/(((S4-R4+1)/7)) -> 6.9808743 | R4: 45292 | S4: 45657
A5: Dead Fish (Rotten) | B5: Bad | C5: 4th-Curr | E5: =COUNTIFS(Beans!B:B, A5) -> 88 | F5: =IF(E4+E5 = 0, "n/a", E5/(E4+E5)) -> 0.68217054 | H5: 2025 | I5: ='2025 Summary'!B76 -> 39 | J5: ='2025 Summary'!B77 -> 0.30952381 | K5: ='2025 Summary'!C76 -> 87 | L5: ='2025 Summary'!C77 -> 0.69047619 | M5: ='2025 Summary'!D76 -> 0 | N5: =I5+K5+M5 -> 126 | O5: =N5/(S5-R5+1) -> 0.34520548 | P5: =N5/(((S5-R5+1)/7)*5) -> 0.48328767 | Q5: =N5/(((S5-R5+1)/7)) -> 2.4164384 | R5: 45658 | S5: 46022
A6: Berry Blue | B6: Good | C6: 1st-Curr | E6: =COUNTIFS(Beans!B:B, A6) -> 8 | F6: =IF(E6+E7 = 0, "n/a", E6/(E6+E7)) -> 0.22857143 | H6: 2026 | I6: ='2026 Summary'!B76 -> 25 | J6: ='2026 Summary'!B77 -> 0.29761905 | K6: ='2026 Summary'!C76 -> 59 | L6: ='2026 Summary'!C77 -> 0.70238095 | M6: ='2026 Summary'!D76 -> 0 | N6: =I6+K6+M6 -> 84 | O6: =N6/(S6-R6+1) -> 0.31460674 | P6: =N6/(((S6-R6+1)/7)*5) -> 0.44044944 | Q6: =N6/(((S6-R6+1)/7)) -> 2.2022472 | R6: 46023 | S6: =TODAY() -> 46289
A7: Toothpaste | B7: Bad | C7: 1st-Curr | D7: =D6 | E7: =COUNTIFS(Beans!B:B, A7) -> 27 | F7: =IF(E6+E7 = 0, "n/a", E7/(E6+E7)) -> 0.77142857 | H7: Total | I7: =I2+I3+I4+I5+I6 -> 315 | J7: =I7/(I7+K7) -> 0.26627219 | K7: =K2+K3+K4+K5+K6 -> 868 | L7: =K7/(I7+K7) -> 0.73372781 | M7: =M2+M3+M4+M5+M6 -> 30 | N7: =I7+K7+M7 -> 1213 | O7: =N7/(S7-R7+1) -> 0.84353268 | P7: =N7/(((S7-R7+1)/7)*5) -> 1.1809458 | Q7: =N7/(((S7-R7+1)/7)) -> 5.9047288 | R7: =R2 -> 44852 | S7: =S6 -> 46289
A8: Birthday Cake | B8: Good | C8: 5th-6th | D8: =D9 | E8: =COUNTIFS(Beans!B:B, A8) -> 17 | F8: =IF(E8+E9 = 0, "n/a", E8/(E8+E9)) -> 0.15454545
A9: Dirty Dishwater | B9: Bad | C9: 5th-6th | E9: =COUNTIFS(Beans!B:B, A9) -> 93 | F9: =IF(E8+E9 = 0, "n/a", E9/(E8+E9)) -> 0.84545455 | H9: =CONCATENATE("2022 Beans", " Good: ", I2, " (", ROUND(J2*100,0), "%)", " Bad: ", K2, " (", ROUND(L2*100,0), "%)", " Spicy: ", M2) -> 2022 Beans Good: 20 (31%) Bad: 44 (69%) Spicy: 5 | N9: =CONCATENATE("Kay Good: ", '2022 Summary'!A18, " Bad: ",'2022 Summary'!B18, " Spicy: 1") -> Kay Good: 0 Bad: 1 Spicy: 1
A10: Peach | B10: Good | C10: 1st-Curr | D10: =D11 | E10: =COUNTIFS(Beans!B:B, A10) -> 32 | F10: =IF(E10+E11 = 0, "n/a", E10/(E10+E11)) -> 0.23021583 | H10: =CONCATENATE("2023 Beans", " Good: ", I3, " (", ROUND(J3*100,0), "%)", " Bad: ", K3, " (", ROUND(L3*100,0), "%)", " Spicy: ", M3) -> 2023 Beans Good: 148 (27%) Bad: 396 (73%) Spicy: 25 | N10: ='2023 Summary'!M65 -> Kay Good: 0 Bad: 1 Spicy: 1 | Q10: ='2023 Summary'!M68 -> Milton Good:0 Bad 3: Spicy: 0
A11: Barf | B11: Bad | C11: 1st-Curr | E11: =COUNTIFS(Beans!B:B, A11) -> 107 | F11: =IF(E10+E11 = 0, "n/a", E11/(E10+E11)) -> 0.76978417 | H11: =CONCATENATE("2024 Beans", " Good: ", I4, " (", ROUND(J4*100,0), "%)", " Bad: ", K4, " (", ROUND(L4*100,0), "%)", " Spicy: ", M4) -> 2024 Beans Good: 83 (23%) Bad: 282 (77%) Spicy: 0 | N11: ='2024 Summary'!L76 -> Kay Good: 1 Bad: 1 Spicy: 0
A12: Tutti Fruitti | B12: Good | C12: 3rd-Curr | D12: =D13 | E12: =COUNTIFS(Beans!B:B, A12) -> 34 | F12: =IF(E12+E13 = 0, "n/a", E12/(E12+E13)) -> 0.25757576 | H12: =CONCATENATE("2025 Beans", " Good: ", I5, " (", ROUND(J5*100,0), "%)", " Bad: ", K5, " (", ROUND(L5*100,0), "%)", " Spicy: ", M5) -> 2025 Beans Good: 39 (31%) Bad: 87 (69%) Spicy: 0 | N12: ='2025 Summary'!L76 -> Kay Good: 0 Bad: 0 Spicy: 0
A13: Stinky Socks | B13: Bad | C13: 3rd-Curr | E13: =COUNTIFS(Beans!B:B, A13) -> 98 | F13: =IF(E12+E13 = 0, "n/a", E13/(E12+E13)) -> 0.74242424 | H13: =CONCATENATE("2026 Beans", " Good: ", I6, " (", ROUND(J6*100,0), "%)", " Bad: ", K6, " (", ROUND(L6*100,0), "%)", " Spicy: ", M6) -> 2026 Beans Good: 25 (30%) Bad: 59 (70%) Spicy: 0 | N13: ='2026 Summary'!L76 -> Kay Good: 0 Bad: 0 Spicy: 0
A14: Pomegranate | B14: Good | C14: 6th-Curr | D14: =D15 | E14: =COUNTIFS(Beans!B:B, A14) -> 50 | F14: =IF(E14+E15 = 0, "n/a", E14/(E14+E15)) -> 0.37313433
A15: Old Bandage | B15: Bad | C15: 6th-Curr | E15: =COUNTIFS(Beans!B:B, A15) -> 84 | F15: =IF(E14+E15 = 0, "n/a", E15/(E14+E15)) -> 0.62686567 | H15: =CONCATENATE("Overall Beans: ", I7+K7+M7," Good: ", I7, " (", ROUND(J7*100,0), "%)", " Bad: ", K7, " (", ROUND(L7*100,0), "%)", " Spicy: ", M7) -> Overall Beans: 1213 Good: 315 (27%) Bad: 868 (73%) Spicy: 30 | O15: Kay Good: 1 Bad: 3 Spicy 2 | R15: Milton Good 0: Bad 3: Spicy 0
A16: Toasted Marshmallow | B16: Good | C16: 5th-Curr | D16: =D17 | E16: =COUNTIFS(Beans!B:B, A16) -> 31 | F16: =IF(E16+E17 = 0, "n/a", E16/(E16+E17)) -> 0.28971963
A17: Stink Bug | B17: Bad | C17: 5th-Curr | E17: =COUNTIFS(Beans!B:B, A17) -> 76 | F17: =IF(E16+E17 = 0, "n/a", E17/(E16+E17)) -> 0.71028037 | H17: =CONCATENATE("Most good beans in a row: ", MAX(Beans!D:D)) -> Most good beans in a row: 5 | L17: =CONCATENATE("Average good beans in a row: ", ROUND(SUM(Beans!D:D)/K3,0)) -> Average good beans in a row: 1 | P17: =CONCATENATE("Median good beans in a row: ", (MEDIAN(Beans!D:D))) -> Median good beans in a row: 0
A18: Cappuccino | B18: Good | C18: 6th-Curr | D18: =D19 | E18: =COUNTIFS(Beans!B:B, A18) -> 31 | F18: =IF(E18+E19 = 0, "n/a", E18/(E18+E19)) -> 0.29245283 | H18: =CONCATENATE("Most bad beans in a row: ", MAX(Beans!E:E)) -> Most bad beans in a row: 22 | L18: =CONCATENATE("Average bad beans in a row: ", ROUND(SUM(Beans!E:E)/I3,0)) -> Average bad beans in a row: 24 | P18: =CONCATENATE("Median bad beans in a row: ", (MEDIAN(Beans!E:E))) -> Median bad beans in a row: 2
A19: Liver & Onion | B19: Bad | C19: 6th-Curr | E19: =COUNTIFS(Beans!B:B, A19) -> 75 | F19: =IF(E18+E19 = 0, "n/a", E19/(E18+E19)) -> 0.70754717
A20: Buttered Popcorn | B20: Good | C20: 1st-6th | D20: =D21 | E20: =COUNTIFS(Beans!B:B, A20) -> 36 | F20: =IF(E20+E21 = 0, "n/a", E20/(E20+E21)) -> 0.34951456 | H20: =CONCATENATE("Most beans in a day: ", MAX(Beans!G:G)) -> Most beans in a day: 33 | L20: =CONCATENATE("Average beans in a day: ", ROUND(AVERAGE(Beans!G:G),1)) -> Average beans in a day: 3.5 | P20: =CONCATENATE("Median beans in a day: ", (MEDIAN(Beans!G:G))) -> Median beans in a day: 2
A21: Rotten Egg | B21: Bad | C21: 1st-6th | E21: =COUNTIFS(Beans!B:B, A21) -> 67 | F21: =IF(E20+E21 = 0, "n/a", E21/(E20+E21)) -> 0.65048544 | H21: =CONCATENATE("Most beans in a month: ", MAX(Beans!H:H)) -> Most beans in a month: 74 | L21: =CONCATENATE("Average beans in a month: ", ROUND(AVERAGE(Beans!H:H),1)) -> Average beans in a month: 21.1
A22: Chocolate Pudding | B22: Good | C22: 2nd-5th | D22: =D23 | E22: =COUNTIFS(Beans!B:B, A22) -> 1 | F22: =IF(E22+E23 = 0, "n/a", E22/(E22+E23)) -> 0.058823529
A23: Dog Food | B23: Bad | C23: 2nd-5th | E23: =COUNTIFS(Beans!B:B, A23) -> 16 | F23: =IF(E22+E23 = 0, "n/a", E23/(E22+E23)) -> 0.94117647
A24: Coconut | B24: Good | C24: 4th-5th | D24: =D25 | E24: =COUNTIFS(Beans!B:B, A24) -> 6 | F24: =IF(E24+E25 = 0, "n/a", E24/(E24+E25)) -> 0.66666667
A25: Spoiled Milk | B25: Bad | C25: 4th-5th | E25: =COUNTIFS(Beans!B:B, A25) -> 3 | F25: =IF(E24+E25 = 0, "n/a", E25/(E24+E25)) -> 0.33333333
A26: Top Banana | B26: Good | C26: 7th-Curr | E26: =COUNTIFS(Beans!B:B, A26) -> 2 | F26: =IF(E26+E27 = 0, "n/a", E26/(E26+E27)) -> 0.11111111
A27: Wet Dog | B27: Bad | C27: 7th-Curr | D27: =D26 | E27: =COUNTIFS(Beans!B:B, A27) -> 16 | F27: =IF(E26+E27 = 0, "n/a", E27/(E26+E27)) -> 0.88888889
A28: Licorice | B28: Good | C28: 7th-Curr | E28: =COUNTIFS(Beans!B:B, A28) -> 4 | F28: =IF(E28+E29 = 0, "n/a", E28/(E28+E29)) -> 0.4
A29: Burnt Rubber | B29: Bad | C29: 7th-Curr | D29: =D28 | E29: =COUNTIFS(Beans!B:B, A29) -> 6 | F29: =IF(E28+E29 = 0, "n/a", E29/(E28+E29)) -> 0.6
A30: Sriracha | B30: Spicy | C30: Firey Five | E30: =COUNTIFS(Beans!B:B, A30) -> 1 | F30: =IF(E30+E31+E32+E33+E34 = 0, "n/a", E30/(E30+E31+E32+E33+E34)) -> 0.033333333
A31: Jalapeño | B31: Spicy | C31: Firey Five | E31: =COUNTIFS(Beans!B:B, A31) -> 3 | F31: =IF(E30+E31+E32+E33+E34 = 0, "n/a", E31/(E30+E31+E32+E33+E34)) -> 0.1
A32: Cayenne | B32: Spicy | C32: Firey Five | E32: =COUNTIFS(Beans!B:B, A32) -> 3 | F32: =IF(E30+E31+E32+E33+E34 = 0, "n/a", E32/(E30+E31+E32+E33+E34)) -> 0.1
A33: Habanero | B33: Spicy | C33: Firey Five | E33: =COUNTIFS(Beans!B:B, A33) -> 11 | F33: =IF(E30+E31+E32+E33+E34 = 0, "n/a", E33/(E30+E31+E32+E33+E34)) -> 0.36666667
A34: Carolina Reaper | B34: Spicy | C34: Firey Five | E34: =COUNTIFS(Beans!B:B, A34) -> 12 | F34: =IF(E30+E31+E32+E33+E34 = 0, "n/a", E34/(E30+E31+E32+E33+E34)) -> 0.4
A35: Mystery Bean (Good) | B35: Good | C35: ? | E35: =COUNTIFS(Beans!B:B, A35) -> 4 | F35: =IF(E35+E36 = 0, "n/a", E35/(E35+E36)) -> 0.66666667
A36: Mystery Bean (Bad) | B36: Bad | C36: ? | E36: =COUNTIFS(Beans!B:B, A36) -> 2 | F36: =IF(E35+E36 = 0, "n/a", E36/(E35+E36)) -> 0.33333333
E37: =SUM(E2:E36) -> 1213

Sheet Beans
A1: Date | B1: Flavor | C1: Type look up | D1: Good in a row | E1: Bad in a row | F1: Beans in a row | G1: Bean of the Day | H1: Bean of the Month | I1: Bean of the Year | K1: Vod | L1: Notes
A2: 44852 | B2: Dirty Dishwater | C2: =IFERROR(VLOOKUP(B2,'Overall Bean Summary'!A$2:B$36,2,FALSE),"") -> Bad | D2: 0 | E2: 1 | F2: 1 | G2: 1 | H2: 1 | I2: 1 | K2: Bean Episode 1 | L2: NEW BOX | M2: Good | N2: Bad | O2: Good | P2: Bad
A3: 44853 | B3: Toasted Marshmallow | C3: =IFERROR(VLOOKUP(B3,'Overall Bean Summary'!A$2:B$36,2,FALSE),"") -> Good | D3: =IF(A3 <> "", IF(C3 = "Spicy", D2, IF(C3 = "Good", D2+1, 0)), "") -> 1 | E3: =IF(A3 <> "", IF(C3 = "Spicy", E2, IF(C3 = "Bad", E2+1 , 0)), "") -> 0 | F3: =IF(B3 <> "", if(B3 = B2, F2+1, 1) ,"") -> 1 | G3: =IF(C3 <> "", IF(DAY(A2) = DAY(A3), G2+1, 1) ,"") -> 1 | H3: =IF(C3 <> "", IF(MONTH(A2) = MONTH(A3), H2+1, 1) ,"") -> 2 | I3: =IF(C3 <> "", IF(YEAR(A2) = YEAR(A3), I2+1, 1) ,"") -> 2 | K3: Bean Episode 2 | M3: =COUNTIF(C2:C34, "Good") -> 12 | N3: =COUNTIF(C2:C34, "Bad")+1 -> 22 | O3: =M3/(M3+N3) -> 0.35294118 | P3: =N3/(M3+N3) -> 0.64705882
A4: 44854 | B4: Toothpaste | C4: =IFERROR(VLOOKUP(B4,'Overall Bean Summary'!A$2:B$36,2,FALSE),"") -> Bad | D4: =IF(A4 <> "", IF(C4 = "Spicy", D3, IF(C4 = "Good", D3+1, 0)), "") -> 0 | E4: =IF(A4 <> "", IF(C4 = "Spicy", E3, IF(C4 = "Bad", E3+1 , 0)), "") -> 1 | F4: =IF(B4 <> "", if(B4 = B3, F3+1, 1) ,"") -> 1 | G4: =IF(C4 <> "", IF(DAY(A3) = DAY(A4), G3+1, 1) ,"") -> 1 | H4: =IF(C4 <> "", IF(MONTH(A3) = MONTH(A4), H3+1, 1) ,"") -> 3 | I4: =IF(C4 <> "", IF(YEAR(A3) = YEAR(A4), I3+1, 1) ,"") -> 3 | K4: Bean Episode 3
A5: 44855 | B5: Tutti Fruitti | C5: =IFERROR(VLOOKUP(B5,'Overall Bean Summary'!A$2:B$36,2,FALSE),"") -> Good | D5: =IF(A5 <> "", IF(C5 = "Spicy", D4, IF(C5 = "Good", D4+1, 0)), "") -> 1 | E5: =IF(A5 <> "", IF(C5 = "Spicy", E4, IF(C5 = "Bad", E4+1 , 0)), "") -> 0 | F5: =IF(B5 <> "", if(B5 = B4, F4+1, 1) ,"") -> 1 | G5: =IF(C5 <> "", IF(DAY(A4) = DAY(A5), G4+1, 1) ,"") -> 1 | H5: =IF(C5 <> "", IF(MONTH(A4) = MONTH(A5), H4+1, 1) ,"") -> 4 | I5: =IF(C5 <> "", IF(YEAR(A4) = YEAR(A5), I4+1, 1) ,"") -> 4 | K5: Bean Episode 4
A6: 44858 | B6: Dead Fish (Rotten) | C6: =IFERROR(VLOOKUP(B6,'Overall Bean Summary'!A$2:B$36,2,FALSE),"") -> Bad | D6: =IF(A6 <> "", IF(C6 = "Spicy", D5, IF(C6 = "Good", D5+1, 0)), "") -> 0 | E6: =IF(A6 <> "", IF(C6 = "Spicy", E5, IF(C6 = "Bad", E5+1 , 0)), "") -> 1 | F6: =IF(B6 <> "", if(B6 = B5, F5+1, 1) ,"") -> 1 | G6: =IF(C6 <> "", IF(DAY(A5) = DAY(A6), G5+1, 1) ,"") -> 1 | H6: =IF(C6 <> "", IF(MONTH(A5) = MONTH(A6), H5+1, 1) ,"") -> 5 | I6: =IF(C6 <> "", IF(YEAR(A5) = YEAR(A6), I5+1, 1) ,"") -> 5 | K6: Bean Episode 5
A7: 44859 | B7: Liver & Onion | C7: =IFERROR(VLOOKUP(B7,'Overall Bean Summary'!A$2:B$36,2,FALSE),"") -> Bad | D7: =IF(A7 <> "", IF(C7 = "Spicy", D6, IF(C7 = "Good", D6+1, 0)), "") -> 0 | E7: =IF(A7 <> "", IF(C7 = "Spicy", E6, IF(C7 = "Bad", E6+1 , 0)), "") -> 2 | F7: =IF(B7 <> "", if(B7 = B6, F6+1, 1) ,"") -> 1 | G7: =IF(C7 <> "", IF(DAY(A6) = DAY(A7), G6+1, 1) ,"") -> 1 | H7: =IF(C7 <> "", IF(MONTH(A6) = MONTH(A7), H6+1, 1) ,"") -> 6 | I7: =IF(C7 <> "", IF(YEAR(A6) = YEAR(A7), I6+1, 1) ,"") -> 6 | K7: Bean Episode 6
A8: 44860 | B8: Birthday Cake | C8: =IFERROR(VLOOKUP(B8,'Overall Bean Summary'!A$2:B$36,2,FALSE),"") -> Good | D8: =IF(A8 <> "", IF(C8 = "Spicy", D7, IF(C8 = "Good", D7+1, 0)), "") -> 1 | E8: =IF(A8 <> "", IF(C8 = "Spicy", E7, IF(C8 = "Bad", E7+1 , 0)), "") -> 0 | F8: =IF(B8 <> "", if(B8 = B7, F7+1, 1) ,"") -> 1 | G8: =IF(C8 <> "", IF(DAY(A7) = DAY(A8), G7+1, 1) ,"") -> 1 | H8: =IF(C8 <> "", IF(MONTH(A7) = MONTH(A8), H7+1, 1) ,"") -> 7 | I8: =IF(C8 <> "", IF(YEAR(A7) = YEAR(A8), I7+1, 1) ,"") -> 7 | K8: Bean Episode 7
A9: 44861 | B9: Peach | C9: =IFERROR(VLOOKUP(B9,'Overall Bean Summary'!A$2:B$36,2,FALSE),"") -> Good | D9: =IF(A9 <> "", IF(C9 = "Spicy", D8, IF(C9 = "Good", D8+1, 0)), "") -> 2 | E9: =IF(A9 <> "", IF(C9 = "Spicy", E8, IF(C9 = "Bad", E8+1 , 0)), "") -> 0 | F9: =IF(B9 <> "", if(B9 = B8, F8+1, 1) ,"") -> 1 | G9: =IF(C9 <> "", IF(DAY(A8) = DAY(A9), G8+1, 1) ,"") -> 1 | H9: =IF(C9 <> "", IF(MONTH(A8) = MONTH(A9), H8+1, 1) ,"") -> 8 | I9: =IF(C9 <> "", IF(YEAR(A8) = YEAR(A9), I8+1, 1) ,"") -> 8 | K9: Bean Episode 8
A10: 44862 | B10: Stinky Socks | C10: =IFERROR(VLOOKUP(B10,'Overall Bean Summary'!A$2:B$36,2,FALSE),"") -> Bad | D10: =IF(A10 <> "", IF(C10 = "Spicy", D9, IF(C10 = "Good", D9+1, 0)), "") -> 0 | E10: =IF(A10 <> "", IF(C10 = "Spicy", E9, IF(C10 = "Bad", E9+1 , 0)), "") -> 1 | F10: =IF(B10 <> "", if(B10 = B9, F9+1, 1) ,"") -> 1 | G10: =IF(C10 <> "", IF(DAY(A9) = DAY(A10), G9+1, 1) ,"") -> 1 | H10: =IF(C10 <> "", IF(MONTH(A9) = MONTH(A10), H9+1, 1) ,"") -> 9 | I10: =IF(C10 <> "", IF(YEAR(A9) = YEAR(A10), I9+1, 1) ,"") -> 9 | K10: Bean Episode 9
A11: 44865 | B11: Peach | C11: =IFERROR(VLOOKUP(B11,'Overall Bean Summary'!A$2:B$36,2,FALSE),"") -> Good | D11: =IF(A11 <> "", IF(C11 = "Spicy", D10, IF(C11 = "Good", D10+1, 0)), "") -> 1 | E11: =IF(A11 <> "", IF(C11 = "Spicy", E10, IF(C11 = "Bad", E10+1 , 0)), "") -> 0 | F11: =IF(B11 <> "", if(B11 = B10, F10+1, 1) ,"") -> 1 | G11: =IF(C11 <> "", IF(DAY(A10) = DAY(A11), G10+1, 1) ,"") -> 1 | H11: =IF(C11 <> "", IF(MONTH(A10) = MONTH(A11), H10+1, 1) ,"") -> 10 | I11: =IF(C11 <> "", IF(YEAR(A10) = YEAR(A11), I10+1, 1) ,"") -> 10 | K11: Bean Episode 10
A12: 44866 | B12: Stink Bug | C12: =IFERROR(VLOOKUP(B12,'Overall Bean Summary'!A$2:B$36,2,FALSE),"") -> Bad | D12: =IF(A12 <> "", IF(C12 = "Spicy", D11, IF(C12 = "Good", D11+1, 0)), "") -> 0 | E12: =IF(A12 <> "", IF(C12 = "Spicy", E11, IF(C12 = "Bad", E11+1 , 0)), "") -> 1 | F12: =IF(B12 <> "", if(B12 = B11, F11+1, 1) ,"") -> 1 | G12: =IF(C12 <> "", IF(DAY(A11) = DAY(A12), G11+1, 1) ,"") -> 1 | H12: =IF(C12 <> "", IF(MONTH(A11) = MONTH(A12), H11+1, 1) ,"") -> 1 | I12: =IF(C12 <> "", IF(YEAR(A11) = YEAR(A12), I11+1, 1) ,"") -> 11 | K12: Bean Episode 11
A13: 44867 | B13: Strawberry Smoothie | C13: =IFERROR(VLOOKUP(B13,'Overall Bean Summary'!A$2:B$36,2,FALSE),"") -> Good | D13: =IF(A13 <> "", IF(C13 = "Spicy", D12, IF(C13 = "Good", D12+1, 0)), "") -> 1 | E13: =IF(A13 <> "", IF(C13 = "Spicy", E12, IF(C13 = "Bad", E12+1 , 0)), "") -> 0 | F13: =IF(B13 <> "", if(B13 = B12, F12+1, 1) ,"") -> 1 | G13: =IF(C13 <> "", IF(DAY(A12) = DAY(A13), G12+1, 1) ,"") -> 1 | H13: =IF(C13 <> "", IF(MONTH(A12) = MONTH(A13), H12+1, 1) ,"") -> 2 | I13: =IF(C13 <> "", IF(YEAR(A12) = YEAR(A13), I12+1, 1) ,"") -> 12 | K13: Bean Episode 12
A14: 44868 | B14: Peach | C14: =IFERROR(VLOOKUP(B14,'Overall Bean Summary'!A$2:B$36,2,FALSE),"") -> Good | D14: =IF(A14 <> "", IF(C14 = "Spicy", D13, IF(C14 = "Good", D13+1, 0)), "") -> 2 | E14: =IF(A14 <> "", IF(C14 = "Spicy", E13, IF(C14 = "Bad", E13+1 , 0)), "") -> 0 | F14: =IF(B14 <> "", if(B14 = B13, F13+1, 1) ,"") -> 1 | G14: =IF(C14 <> "", IF(DAY(A13) = DAY(A14), G13+1, 1) ,"") -> 1 | H14: =IF(C14 <> "", IF(MONTH(A13) = MONTH(A14), H13+1, 1) ,"") -> 3 | I14: =IF(C14 <> "", IF(YEAR(A13) = YEAR(A14), I13+1, 1) ,"") -> 13 | K14: Bean Episode 13
A15: 44869 | B15: Buttered Popcorn | C15: =IFERROR(VLOOKUP(B15,'Overall Bean Summary'!A$2:B$36,2,FALSE),"") -> Good | D15: =IF(A15 <> "", IF(C15 = "Spicy", D14, IF(C15 = "Good", D14+1, 0)), "") -> 3 | E15: =IF(A15 <> "", IF(C15 = "Spicy", E14, IF(C15 = "Bad", E14+1 , 0)), "") -> 0 | F15: =IF(B15 <> "", if(B15 = B14, F14+1, 1) ,"") -> 1 | G15: =IF(C15 <> "", IF(DAY(A14) = DAY(A15), G14+1, 1) ,"") -> 1 | H15: =IF(C15 <> "", IF(MONTH(A14) = MONTH(A15), H14+1, 1) ,"") -> 4 | I15: =IF(C15 <> "", IF(YEAR(A14) = YEAR(A15), I14+1, 1) ,"") -> 14 | K15: Bean Episode 14
... A17: 44873 | B17: Juicy Pear | C17: =IFERROR(VLOOKUP(B17,'Overall Bean Summary'!A$2:B$36,2,FALSE),"") -> Good | D17: =IF(A17 <> "", IF(C17 = "Spicy", D16, IF(C17 = "Good", D16+1, 0)), "") -> 1 | E17: =IF(A17 <> "", IF(C17 = "Spicy", E16, IF(C17 = "Bad", E16+1 , 0)), "") -> 0 | F17: =IF(B17 <> "", if(B17 = B16, F16+1, 1) ,"") -> 1 | G17: =IF(C17 <> "", IF(DAY(A16) = DAY(A17), G16+1, 1) ,"") -> 1 | H17: =IF(C17 <> "", IF(MONTH(A16) = MONTH(A17), H16+1, 1) ,"") -> 6 | I17: =IF(C17 <> "", IF(YEAR(A16) = YEAR(A17), I16+1, 1) ,"") -> 16 | K17: Bean Episode 16
A18: 44874 | B18: Rotten Egg | C18: =IFERROR(VLOOKUP(B18,'Overall Bean Summary'!A$2:B$36,2,FALSE),"") -> Bad | D18: =IF(A18 <> "", IF(C18 = "Spicy", D17, IF(C18 = "Good", D17+1, 0)), "") -> 0 | E18: =IF(A18 <> "", IF(C18 = "Spicy", E17, IF(C18 = "Bad", E17+1 , 0)), "") -> 1 | F18: =IF(B18 <> "", if(B18 = B17, F17+1, 1) ,"") -> 1 | G18: =IF(C18 <> "", IF(DAY(A17) = DAY(A18), G17+1, 1) ,"") -> 1 | H18: =IF(C18 <> "", IF(MONTH(A17) = MONTH(A18), H17+1, 1) ,"") -> 7 | I18: =IF(C18 <> "", IF(YEAR(A17) = YEAR(A18), I17+1, 1) ,"") -> 17 | K18: Bean Episode 17 | L18: Kay Bean | M18: Rotten Egg
A19: 44875 | B19: Stinky Socks | C19: =IFERROR(VLOOKUP(B19,'Overall Bean Summary'!A$2:B$36,2,FALSE),"") -> Bad | D19: =IF(A19 <> "", IF(C19 = "Spicy", D18, IF(C19 = "Good", D18+1, 0)), "") -> 0 | E19: =IF(A19 <> "", IF(C19 = "Spicy", E18, IF(C19 = "Bad", E18+1 , 0)), "") -> 2 | F19: =IF(B19 <> "", if(B19 = B18, F18+1, 1) ,"") -> 1 | G19: =IF(C19 <> "", IF(DAY(A18) = DAY(A19), G18+1, 1) ,"") -> 1 | H19: =IF(C19 <> "", IF(MONTH(A18) = MONTH(A19), H18+1, 1) ,"") -> 8 | I19: =IF(C19 <> "", IF(YEAR(A18) = YEAR(A19), I18+1, 1) ,"") -> 18 | K19: Bean Episode 18
A20: 44876 | B20: Liver & Onion | C20: =IFERROR(VLOOKUP(B20,'Overall Bean Summary'!A$2:B$36,2,FALSE),"") -> Bad | D20: =IF(A20 <> "", IF(C20 = "Spicy", D19, IF(C20 = "Good", D19+1, 0)), "") -> 0 | E20: =IF(A20 <> "", IF(C20 = "Spicy", E19, IF(C20 = "Bad", E19+1 , 0)), "") -> 3 | F20: =IF(B20 <> "", if(B20 = B19, F19+1, 1) ,"") -> 1 | G20: =IF(C20 <> "", IF(DAY(A19) = DAY(A20), G19+1, 1) ,"") -> 1 | H20: =IF(C20 <> "", IF(MONTH(A19) = MONTH(A20), H19+1, 1) ,"") -> 9 | I20: =IF(C20 <> "", IF(YEAR(A19) = YEAR(A20), I19+1, 1) ,"") -> 19 | K20: Bean Episode 19 | M20: Korygg - Techsmith 351
A21: 44879 | B21: Berry Blue | C21: =IFERROR(VLOOKUP(B21,'Overall Bean Summary'!A$2:B$36,2,FALSE),"") -> Good | D21: =IF(A21 <> "", IF(C21 = "Spicy", D20, IF(C21 = "Good", D20+1, 0)), "") -> 1 | E21: =IF(A21 <> "", IF(C21 = "Spicy", E20, IF(C21 = "Bad", E20+1 , 0)), "") -> 0 | F21: =IF(B21 <> "", if(B21 = B20, F20+1, 1) ,"") -> 1 | G21: =IF(C21 <> "", IF(DAY(A20) = DAY(A21), G20+1, 1) ,"") -> 1 | H21: =IF(C21 <> "", IF(MONTH(A20) = MONTH(A21), H20+1, 1) ,"") -> 10 | I21: =IF(C21 <> "", IF(YEAR(A20) = YEAR(A21), I20+1, 1) ,"") -> 20 | K21: Bean Episode 20
A22: 44880 | B22: Barf | C22: =IFERROR(VLOOKUP(B22,'Overall Bean Summary'!A$2:B$36,2,FALSE),"") -> Bad | D22: =IF(A22 <> "", IF(C22 = "Spicy", D21, IF(C22 = "Good", D21+1, 0)), "") -> 0 | E22: =IF(A22 <> "", IF(C22 = "Spicy", E21, IF(C22 = "Bad", E21+1 , 0)), "") -> 1 | F22: =IF(B22 <> "", if(B22 = B21, F21+1, 1) ,"") -> 1 | G22: =IF(C22 <> "", IF(DAY(A21) = DAY(A22), G21+1, 1) ,"") -> 1 | H22: =IF(C22 <> "", IF(MONTH(A21) = MONTH(A22), H21+1, 1) ,"") -> 11 | I22: =IF(C22 <> "", IF(YEAR(A21) = YEAR(A22), I21+1, 1) ,"") -> 21 | K22: Bean Episode 21
A23: 44881 | B23: Cappuccino | C23: =IFERROR(VLOOKUP(B23,'Overall Bean Summary'!A$2:B$36,2,FALSE),"") -> Good | D23: =IF(A23 <> "", IF(C23 = "Spicy", D22, IF(C23 = "Good", D22+1, 0)), "") -> 1 | E23: =IF(A23 <> "", IF(C23 = "Spicy", E22, IF(C23 = "Bad", E22+1 , 0)), "") -> 0 | F23: =IF(B23 <> "", if(B23 = B22, F22+1, 1) ,"") -> 1 | G23: =IF(C23 <> "", IF(DAY(A22) = DAY(A23), G22+1, 1) ,"") -> 1 | H23: =IF(C23 <> "", IF(MONTH(A22) = MONTH(A23), H22+1, 1) ,"") -> 12 | I23: =IF(C23 <> "", IF(YEAR(A22) = YEAR(A23), I22+1, 1) ,"") -> 22 | K23: Bean Episode 22
A24: 44882 | B24: Liver & Onion | C24: =IFERROR(VLOOKUP(B24,'Overall Bean Summary'!A$2:B$36,2,FALSE),"") -> Bad | D24: =IF(A24 <> "", IF(C24 = "Spicy", D23, IF(C24 = "Good", D23+1, 0)), "") -> 0 | E24: =IF(A24 <> "", IF(C24 = "Spicy", E23, IF(C24 = "Bad", E23+1 , 0)), "") -> 1 | F24: =IF(B24 <> "", if(B24 = B23, F23+1, 1) ,"") -> 1 | G24: =IF(C24 <> "", IF(DAY(A23) = DAY(A24), G23+1, 1) ,"") -> 1 | H24: =IF(C24 <> "", IF(MONTH(A23) = MONTH(A24), H23+1, 1) ,"") -> 13 | I24: =IF(C24 <> "", IF(YEAR(A23) = YEAR(A24), I23+1, 1) ,"") -> 23 | K24: Bean Episode 23
A25: 44882 | B25: Cappuccino | C25: =IFERROR(VLOOKUP(B25,'Overall Bean Summary'!A$2:B$36,2,FALSE),"") -> Good | D25: =IF(A25 <> "", IF(C25 = "Spicy", D24, IF(C25 = "Good", D24+1, 0)), "") -> 1 | E25: =IF(A25 <> "", IF(C25 = "Spicy", E24, IF(C25 = "Bad", E24+1 , 0)), "") -> 0 | F25: =IF(B25 <> "", if(B25 = B24, F24+1, 1) ,"") -> 1 | G25: =IF(C25 <> "", IF(DAY(A24) = DAY(A25), G24+1, 1) ,"") -> 2 | H25: =IF(C25 <> "", IF(MONTH(A24) = MONTH(A25), H24+1, 1) ,"") -> 14 | I25: =IF(C25 <> "", IF(YEAR(A24) = YEAR(A25), I24+1, 1) ,"") -> 24 | K25: Bean Episode 23
A26: 44883 | B26: Barf | C26: =IFERROR(VLOOKUP(B26,'Overall Bean Summary'!A$2:B$36,2,FALSE),"") -> Bad | D26: =IF(A26 <> "", IF(C26 = "Spicy", D25, IF(C26 = "Good", D25+1, 0)), "") -> 0 | E26: =IF(A26 <> "", IF(C26 = "Spicy", E25, IF(C26 = "Bad", E25+1 , 0)), "") -> 1 | F26: =IF(B26 <> "", if(B26 = B25, F25+1, 1) ,"") -> 1 | G26: =IF(C26 <> "", IF(DAY(A25) = DAY(A26), G25+1, 1) ,"") -> 1 | H26: =IF(C26 <> "", IF(MONTH(A25) = MONTH(A26), H25+1, 1) ,"") -> 15 | I26: =IF(C26 <> "", IF(YEAR(A25) = YEAR(A26), I25+1, 1) ,"") -> 25 | K26: Bean Episode 24
A27: 44886 | B27: Old Bandage | C27: =IFERROR(VLOOKUP(B27,'Overall Bean Summary'!A$2:B$36,2,FALSE),"") -> Bad | D27: =IF(A27 <> "", IF(C27 = "Spicy", D26, IF(C27 = "Good", D26+1, 0)), "") -> 0 | E27: =IF(A27 <> "", IF(C27 = "Spicy", E26, IF(C27 = "Bad", E26+1 , 0)), "") -> 2 | F27: =IF(B27 <> "", if(B27 = B26, F26+1, 1) ,"") -> 1 | G27: =IF(C27 <> "", IF(DAY(A26) = DAY(A27), G26+1, 1) ,"") -> 1 | H27: =IF(C27 <> "", IF(MONTH(A26) = MONTH(A27), H26+1, 1) ,"") -> 16 | I27: =IF(C27 <> "", IF(YEAR(A26) = YEAR(A27), I26+1, 1) ,"") -> 26 | K27: Bean Episode 25
A28: 44887 | B28: Dirty Dishwater | C28: =IFERROR(VLOOKUP(B28,'Overall Bean Summary'!A$2:B$36,2,FALSE),"") -> Bad | D28: =IF(A28 <> "", IF(C28 = "Spicy", D27, IF(C28 = "Good", D27+1, 0)), "") -> 0 | E28: =IF(A28 <> "", IF(C28 = "Spicy", E27, IF(C28 = "Bad", E27+1 , 0)), "") -> 3 | F28: =IF(B28 <> "", if(B28 = B27, F27+1, 1) ,"") -> 1 | G28: =IF(C28 <> "", IF(DAY(A27) = DAY(A28), G27+1, 1) ,"") -> 1 | H28: =IF(C28 <> "", IF(MONTH(A27) = MONTH(A28), H27+1, 1) ,"") -> 17 | I28: =IF(C28 <> "", IF(YEAR(A27) = YEAR(A28), I27+1, 1) ,"") -> 27 | K28: Bean Episode 26
A29: 44888 | B29: Toothpaste | C29: =IFERROR(VLOOKUP(B29,'Overall Bean Summary'!A$2:B$36,2,FALSE),"") -> Bad | D29: =IF(A29 <> "", IF(C29 = "Spicy", D28, IF(C29 = "Good", D28+1, 0)), "") -> 0 | E29: =IF(A29 <> "", IF(C29 = "Spicy", E28, IF(C29 = "Bad", E28+1 , 0)), "") -> 4 | F29: =IF(B29 <> "", if(B29 = B28, F28+1, 1) ,"") -> 1 | G29: =IF(C29 <> "", IF(DAY(A28) = DAY(A29), G28+1, 1) ,"") -> 1 | H29: =IF(C29 <> "", IF(MONTH(A28) = MONTH(A29), H28+1, 1) ,"") -> 18 | I29: =IF(C29 <> "", IF(YEAR(A28) = YEAR(A29), I28+1, 1) ,"") -> 28 | K29: Bean Episode 27
A30: 44889 | B30: Dead Fish (Rotten) | C30: =IFERROR(VLOOKUP(B30,'Overall Bean Summary'!A$2:B$36,2,FALSE),"") -> Bad | D30: =IF(A30 <> "", IF(C30 = "Spicy", D29, IF(C30 = "Good", D29+1, 0)), "") -> 0 | E30: =IF(A30 <> "", IF(C30 = "Spicy", E29, IF(C30 = "Bad", E29+1 , 0)), "") -> 5 | F30: =IF(B30 <> "", if(B30 = B29, F29+1, 1) ,"") -> 1 | G30: =IF(C30 <> "", IF(DAY(A29) = DAY(A30), G29+1, 1) ,"") -> 1 | H30: =IF(C30 <> "", IF(MONTH(A29) = MONTH(A30), H29+1, 1) ,"") -> 19 | I30: =IF(C30 <> "", IF(YEAR(A29) = YEAR(A30), I29+1, 1) ,"") -> 29 | K30: Bean Episode 28
A31: 44890 | B31: Dirty Dishwater | C31: =IFERROR(VLOOKUP(B31,'Overall Bean Summary'!A$2:B$36,2,FALSE),"") -> Bad | D31: =IF(A31 <> "", IF(C31 = "Spicy", D30, IF(C31 = "Good", D30+1, 0)), "") -> 0 | E31: =IF(A31 <> "", IF(C31 = "Spicy", E30, IF(C31 = "Bad", E30+1 , 0)), "") -> 6 | F31: =IF(B31 <> "", if(B31 = B30, F30+1, 1) ,"") -> 1 | G31: =IF(C31 <> "", IF(DAY(A30) = DAY(A31), G30+1, 1) ,"") -> 1 | H31: =IF(C31 <> "", IF(MONTH(A30) = MONTH(A31), H30+1, 1) ,"") -> 20 | I31: =IF(C31 <> "", IF(YEAR(A30) = YEAR(A31), I30+1, 1) ,"") -> 30 | K31: Bean Episode 29
A32: 44890 | B32: Dirty Dishwater | C32: =IFERROR(VLOOKUP(B32,'Overall Bean Summary'!A$2:B$36,2,FALSE),"") -> Bad | D32: =IF(A32 <> "", IF(C32 = "Spicy", D31, IF(C32 = "Good", D31+1, 0)), "") -> 0 | E32: =IF(A32 <> "", IF(C32 = "Spicy", E31, IF(C32 = "Bad", E31+1 , 0)), "") -> 7 | F32: =IF(B32 <> "", if(B32 = B31, F31+1, 1) ,"") -> 2 | G32: =IF(C32 <> "", IF(DAY(A31) = DAY(A32), G31+1, 1) ,"") -> 2 | H32: =IF(C32 <> "", IF(MONTH(A31) = MONTH(A32), H31+1, 1) ,"") -> 21 | I32: =IF(C32 <> "", IF(YEAR(A31) = YEAR(A32), I31+1, 1) ,"") -> 31 | K32: Bean Episode 29
A33: 44893 | B33: Rotten Egg | C33: =IFERROR(VLOOKUP(B33,'Overall Bean Summary'!A$2:B$36,2,FALSE),"") -> Bad | D33: =IF(A33 <> "", IF(C33 = "Spicy", D32, IF(C33 = "Good", D32+1, 0)), "") -> 0 | E33: =IF(A33 <> "", IF(C33 = "Spicy", E32, IF(C33 = "Bad", E32+1 , 0)), "") -> 8 | F33: =IF(B33 <> "", if(B33 = B32, F32+1, 1) ,"") -> 1 | G33: =IF(C33 <> "", IF(DAY(A32) = DAY(A33), G32+1, 1) ,"") -> 1 | H33: =IF(C33 <> "", IF(MONTH(A32) = MONTH(A33), H32+1, 1) ,"") -> 22 | I33: =IF(C33 <> "", IF(YEAR(A32) = YEAR(A33), I32+1, 1) ,"") -> 32 | K33: Bean Episode 30
A34: 44894 | B34: Dirty Dishwater | C34: =IFERROR(VLOOKUP(B34,'Overall Bean Summary'!A$2:B$36,2,FALSE),"") -> Bad | D34: =IF(A34 <> "", IF(C34 = "Spicy", D33, IF(C34 = "Good", D33+1, 0)), "") -> 0 | E34: =IF(A34 <> "", IF(C34 = "Spicy", E33, IF(C34 = "Bad", E33+1 , 0)), "") -> 9 | F34: =IF(B34 <> "", if(B34 = B33, F33+1, 1) ,"") -> 1 | G34: =IF(C34 <> "", IF(DAY(A33) = DAY(A34), G33+1, 1) ,"") -> 1 | H34: =IF(C34 <> "", IF(MONTH(A33) = MONTH(A34), H33+1, 1) ,"") -> 23 | I34: =IF(C34 <> "", IF(YEAR(A33) = YEAR(A34), I33+1, 1) ,"") -> 33 | K34: Bean Episode 31 | M34: Good | N34: Bad | O34: Good | P34: Bad
A35: 44896 | B35: Mystery Bean (Good) | C35: =IFERROR(VLOOKUP(B35,'Overall Bean Summary'!A$2:B$36,2,FALSE),"") -> Good | D35: =IF(A35 <> "", IF(C35 = "Spicy", D34, IF(C35 = "Good", D34+1, 0)), "") -> 1 | E35: =IF(A35 <> "", IF(C35 = "Spicy", E34, IF(C35 = "Bad", E34+1 , 0)), "") -> 0 | F35: =IF(B35 <> "", if(B35 = B34, F34+1, 1) ,"") -> 1 | G35: =IF(C35 <> "", IF(DAY(A34) = DAY(A35), G34+1, 1) ,"") -> 1 | H35: =IF(C35 <> "", IF(MONTH(A34) = MONTH(A35), H34+1, 1) ,"") -> 1 | I35: =IF(C35 <> "", IF(YEAR(A34) = YEAR(A35), I34+1, 1) ,"") -> 34 | K35: Bean Episode 32 | L35: Bubblegum?! | M35: =COUNTIF(C35:C113, "Good") -> 19 | N35: =COUNTIF(C35:C113, "Bad") -> 54 | O35: =M35/(M35+N35) -> 0.26027397 | P35: =N35/(M35+N35) -> 0.73972603
A36: 44897 | B36: Barf | C36: =IFERROR(VLOOKUP(B36,'Overall Bean Summary'!A$2:B$36,2,FALSE),"") -> Bad | D36: =IF(A36 <> "", IF(C36 = "Spicy", D35, IF(C36 = "Good", D35+1, 0)), "") -> 0 | E36: =IF(A36 <> "", IF(C36 = "Spicy", E35, IF(C36 = "Bad", E35+1 , 0)), "") -> 1 | F36: =IF(B36 <> "", if(B36 = B35, F35+1, 1) ,"") -> 1 | G36: =IF(C36 <> "", IF(DAY(A35) = DAY(A36), G35+1, 1) ,"") -> 1 | H36: =IF(C36 <> "", IF(MONTH(A35) = MONTH(A36), H35+1, 1) ,"") -> 2 | I36: =IF(C36 <> "", IF(YEAR(A35) = YEAR(A36), I35+1, 1) ,"") -> 35 | K36: Bean Episode 33
A37: 44897 | B37: Pomegranate | C37: =IFERROR(VLOOKUP(B37,'Overall Bean Summary'!A$2:B$36,2,FALSE),"") -> Good | D37: =IF(A37 <> "", IF(C37 = "Spicy", D36, IF(C37 = "Good", D36+1, 0)), "") -> 1 | E37: =IF(A37 <> "", IF(C37 = "Spicy", E36, IF(C37 = "Bad", E36+1 , 0)), "") -> 0 | F37: =IF(B37 <> "", if(B37 = B36, F36+1, 1) ,"") -> 1 | G37: =IF(C37 <> "", IF(DAY(A36) = DAY(A37), G36+1, 1) ,"") -> 2 | H37: =IF(C37 <> "", IF(MONTH(A36) = MONTH(A37), H36+1, 1) ,"") -> 3 | I37: =IF(C37 <> "", IF(YEAR(A36) = YEAR(A37), I36+1, 1) ,"") -> 36 | K37: (no VOD)
A38: 44900 | B38: Dirty Dishwater | C38: =IFERROR(VLOOKUP(B38,'Overall Bean Summary'!A$2:B$36,2,FALSE),"") -> Bad | D38: =IF(A38 <> "", IF(C38 = "Spicy", D37, IF(C38 = "Good", D37+1, 0)), "") -> 0 | E38: =IF(A38 <> "", IF(C38 = "Spicy", E37, IF(C38 = "Bad", E37+1 , 0)), "") -> 1 | F38: =IF(B38 <> "", if(B38 = B37, F37+1, 1) ,"") -> 1 | G38: =IF(C38 <> "", IF(DAY(A37) = DAY(A38), G37+1, 1) ,"") -> 1 | H38: =IF(C38 <> "", IF(MONTH(A37) = MONTH(A38), H37+1, 1) ,"") -> 4 | I38: =IF(C38 <> "", IF(YEAR(A37) = YEAR(A38), I37+1, 1) ,"") -> 37 | K38: Bean Episode 34
A39: 44900 | B39: Dirty Dishwater | C39: =IFERROR(VLOOKUP(B39,'Overall Bean Summary'!A$2:B$36,2,FALSE),"") -> Bad | D39: =IF(A39 <> "", IF(C39 = "Spicy", D38, IF(C39 = "Good", D38+1, 0)), "") -> 0 | E39: =IF(A39 <> "", IF(C39 = "Spicy", E38, IF(C39 = "Bad", E38+1 , 0)), "") -> 2 | F39: =IF(B39 <> "", if(B39 = B38, F38+1, 1) ,"") -> 2 | G39: =IF(C39 <> "", IF(DAY(A38) = DAY(A39), G38+1, 1) ,"") -> 2 | H39: =IF(C39 <> "", IF(MONTH(A38) = MONTH(A39), H38+1, 1) ,"") -> 5 | I39: =IF(C39 <> "", IF(YEAR(A38) = YEAR(A39), I38+1, 1) ,"") -> 38 | K39: Bean Episode 34
A40: 44900 | B40: Dirty Dishwater | C40: =IFERROR(VLOOKUP(B40,'Overall Bean Summary'!A$2:B$36,2,FALSE),"") -> Bad | D40: =IF(A40 <> "", IF(C40 = "Spicy", D39, IF(C40 = "Good", D39+1, 0)), "") -> 0 | E40: =IF(A40 <> "", IF(C40 = "Spicy", E39, IF(C40 = "Bad", E39+1 , 0)), "") -> 3 | F40: =IF(B40 <> "", if(B40 = B39, F39+1, 1) ,"") -> 3 | G40: =IF(C40 <> "", IF(DAY(A39) = DAY(A40), G39+1, 1) ,"") -> 3 | H40: =IF(C40 <> "", IF(MONTH(A39) = MONTH(A40), H39+1, 1) ,"") -> 6 | I40: =IF(C40 <> "", IF(YEAR(A39) = YEAR(A40), I39+1, 1) ,"") -> 39 | K40: Bean Episode 34 | M40: Techsmith 356 - Drock424 - Techsmith of Dirty Dishwater
A41: 44901 | B41: Pomegranate | C41: =IFERROR(VLOOKUP(B41,'Overall Bean Summary'!A$2:B$36,2,FALSE),"") -> Good | D41: =IF(A41 <> "", IF(C41 = "Spicy", D40, IF(C41 = "Good", D40+1, 0)), "") -> 1 | E41: =IF(A41 <> "", IF(C41 = "Spicy", E40, IF(C41 = "Bad", E40+1 , 0)), "") -> 0 | F41: =IF(B41 <> "", if(B41 = B40, F40+1, 1) ,"") -> 1 | G41: =IF(C41 <> "", IF(DAY(A40) = DAY(A41), G40+1, 1) ,"") -> 1 | H41: =IF(C41 <> "", IF(MONTH(A40) = MONTH(A41), H40+1, 1) ,"") -> 7 | I41: =IF(C41 <> "", IF(YEAR(A40) = YEAR(A41), I40+1, 1) ,"") -> 40 | K41: Bean Episode 35 | M41: Techsmith 357 - Malwatch Mando - Toxic Fucks
...

Sheet Not Beans
A1: Date | B1: Flavor | C1: Type | D1: Good in a row | E1: Bad in a row | K1: Vod | L1: Notes
A2: 45043 | B2: Pickled Egg | C2: Egg
A3: 45806 | B3: Sweet - Sour Grape? | C3: Good | D3: 1 | E3: 0 | L3: Sweet or Spicy (ghostpepper) candy rope
A4: 45806 | B4: Sweet - Sour Rhasberry? | C4: Good | D4: =IF(A4 <> "", IF(C4 = "Spicy", D3, IF(C4 = "Good", D3+1, 0)), "") -> 2 | E4: =IF(A4 <> "", IF(C4 = "Spicy", E3, IF(C4 = "Bad", E3+1 , 0)), "") -> 0 | F4: =IF(B4 <> "", if(B4 = B3, F3+1, 1) ,"") -> 1 | G4: =IF(C4 <> "", IF(DAY(A3) = DAY(A4), G3+1, 1) ,"") -> 1 | H4: =IF(C4 <> "", IF(MONTH(A3) = MONTH(A4), H3+1, 1) ,"") -> 1 | I4: =IF(C4 <> "", IF(YEAR(A3) = YEAR(A4), I3+1, 1) ,"") -> 1 | L4: Sweet or Spicy (ghostpepper) candy rope
A5: 45841 | B5: Sweet - Blueberry? | C5: Good | D5: =IF(A5 <> "", IF(C5 = "Spicy", D4, IF(C5 = "Good", D4+1, 0)), "") -> 3 | E5: =IF(A5 <> "", IF(C5 = "Spicy", E4, IF(C5 = "Bad", E4+1 , 0)), "") -> 0 | F5: =IF(B5 <> "", if(B5 = B4, F4+1, 1) ,"") -> 1 | G5: =IF(C5 <> "", IF(DAY(A4) = DAY(A5), G4+1, 1) ,"") -> 1 | H5: =IF(C5 <> "", IF(MONTH(A4) = MONTH(A5), H4+1, 1) ,"") -> 1 | I5: =IF(C5 <> "", IF(YEAR(A4) = YEAR(A5), I4+1, 1) ,"") -> 2
A6: 45841 | B6: Spicy - ? | C6: Bad | D6: =IF(A6 <> "", IF(C6 = "Spicy", D5, IF(C6 = "Good", D5+1, 0)), "") -> 0 | E6: =IF(A6 <> "", IF(C6 = "Spicy", E5, IF(C6 = "Bad", E5+1 , 0)), "") -> 1 | F6: =IF(B6 <> "", if(B6 = B5, F5+1, 1) ,"") -> 1 | G6: =IF(C6 <> "", IF(DAY(A5) = DAY(A6), G5+1, 1) ,"") -> 2 | H6: =IF(C6 <> "", IF(MONTH(A5) = MONTH(A6), H5+1, 1) ,"") -> 2 | I6: =IF(C6 <> "", IF(YEAR(A5) = YEAR(A6), I5+1, 1) ,"") -> 3
T845: Bad
T846: =R846/(Q846+R846) -> #DIV/0!
T938: Bad
T939: =R939/(Q939+R939) -> #DIV/0!
T1027: Bad
T1028: =R1028/(Q1028+R1028) -> #DIV/0!
T1044: Bad
T1045: =R1045/(Q1045+R1045) -> #DIV/0!
C1075: =IFERROR(VLOOKUP(B1075,'Overall Bean Summary'!A$2:B$36,2,FALSE),"") | D1075: =IF(A1075 <> "", IF(C1075 = "Spicy", D1074, IF(C1075 = "Good", D1074+1, 0)), "") | E1075: =IF(A1075 <> "", IF(C1075 = "Spicy", E1074, IF(C1075 = "Bad", E1074+1 , 0)), "") | F1075: =IF(B1075 <> "", if(B1075 = B1074, F1074+1, 1) ,"") | G1075: =IF(C1075 <> "", IF(DAY(A1074) = DAY(A1075), G1074+1, 1) ,"") | H1075: =IF(C1075 <> "", IF(MONTH(A1074) = MONTH(A1075), H1074+1, 1) ,"") | I1075: =IF(C1075 <> "", IF(YEAR(A1074) = YEAR(A1075), I1074+1, 1) ,"")
C1076: =IFERROR(VLOOKUP(B1076,'Overall Bean Summary'!A$2:B$36,2,FALSE),"") | D1076: =IF(A1076 <> "", IF(C1076 = "Spicy", D1075, IF(C1076 = "Good", D1075+1, 0)), "") | E1076: =IF(A1076 <> "", IF(C1076 = "Spicy", E1075, IF(C1076 = "Bad", E1075+1 , 0)), "") | F1076: =IF(B1076 <> "", if(B1076 = B1075, F1075+1, 1) ,"") | G1076: =IF(C1076 <> "", IF(DAY(A1075) = DAY(A1076), G1075+1, 1) ,"") | H1076: =IF(C1076 <> "", IF(MONTH(A1075) = MONTH(A1076), H1075+1, 1) ,"") | I1076: =IF(C1076 <> "", IF(YEAR(A1075) = YEAR(A1076), I1075+1, 1) ,"")
C1077: =IFERROR(VLOOKUP(B1077,'Overall Bean Summary'!A$2:B$36,2,FALSE),"") | D1077: =IF(A1077 <> "", IF(C1077 = "Spicy", D1076, IF(C1077 = "Good", D1076+1, 0)), "") | E1077: =IF(A1077 <> "", IF(C1077 = "Spicy", E1076, IF(C1077 = "Bad", E1076+1 , 0)), "") | F1077: =IF(B1077 <> "", if(B1077 = B1076, F1076+1, 1) ,"") | G1077: =IF(C1077 <> "", IF(DAY(A1076) = DAY(A1077), G1076+1, 1) ,"") | H1077: =IF(C1077 <> "", IF(MONTH(A1076) = MONTH(A1077), H1076+1, 1) ,"") | I1077: =IF(C1077 <> "", IF(YEAR(A1076) = YEAR(A1077), I1076+1, 1) ,"")
C1078: =IFERROR(VLOOKUP(B1078,'Overall Bean Summary'!A$2:B$36,2,FALSE),"") | D1078: =IF(A1078 <> "", IF(C1078 = "Spicy", D1077, IF(C1078 = "Good", D1077+1, 0)), "") | E1078: =IF(A1078 <> "", IF(C1078 = "Spicy", E1077, IF(C1078 = "Bad", E1077+1 , 0)), "") | F1078: =IF(B1078 <> "", if(B1078 = B1077, F1077+1, 1) ,"") | G1078: =IF(C1078 <> "", IF(DAY(A1077) = DAY(A1078), G1077+1, 1) ,"") | H1078: =IF(C1078 <> "", IF(MONTH(A1077) = MONTH(A1078), H1077+1, 1) ,"") | I1078: =IF(C1078 <> "", IF(YEAR(A1077) = YEAR(A1078), I1077+1, 1) ,"")
C1079: =IFERROR(VLOOKUP(B1079,'Overall Bean Summary'!A$2:B$36,2,FALSE),"") | D1079: =IF(A1079 <> "", IF(C1079 = "Spicy", D1078, IF(C1079 = "Good", D1078+1, 0)), "") | E1079: =IF(A1079 <> "", IF(C1079 = "Spicy", E1078, IF(C1079 = "Bad", E1078+1 , 0)), "") | F1079: =IF(B1079 <> "", if(B1079 = B1078, F1078+1, 1) ,"") | G1079: =IF(C1079 <> "", IF(DAY(A1078) = DAY(A1079), G1078+1, 1) ,"") | H1079: =IF(C1079 <> "", IF(MONTH(A1078) = MONTH(A1079), H1078+1, 1) ,"") | I1079: =IF(C1079 <> "", IF(YEAR(A1078) = YEAR(A1079), I1078+1, 1) ,"")
C1080: =IFERROR(VLOOKUP(B1080,'Overall Bean Summary'!A$2:B$36,2,FALSE),"") | D1080: =IF(A1080 <> "", IF(C1080 = "Spicy", D1079, IF(C1080 = "Good", D1079+1, 0)), "") | E1080: =IF(A1080 <> "", IF(C1080 = "Spicy", E1079, IF(C1080 = "Bad", E1079+1 , 0)), "") | F1080: =IF(B1080 <> "", if(B1080 = B1079, F1079+1, 1) ,"") | G1080: =IF(C1080 <> "", IF(DAY(A1079) = DAY(A1080), G1079+1, 1) ,"") | H1080: =IF(C1080 <> "", IF(MONTH(A1079) = MONTH(A1080), H1079+1, 1) ,"") | I1080: =IF(C1080 <> "", IF(YEAR(A1079) = YEAR(A1080), I1079+1, 1) ,"")
C1081: =IFERROR(VLOOKUP(B1081,'Overall Bean Summary'!A$2:B$36,2,FALSE),"") | D1081: =IF(A1081 <> "", IF(C1081 = "Spicy", D1080, IF(C1081 = "Good", D1080+1, 0)), "") | E1081: =IF(A1081 <> "", IF(C1081 = "Spicy", E1080, IF(C1081 = "Bad", E1080+1 , 0)), "") | F1081: =IF(B1081 <> "", if(B1081 = B1080, F1080+1, 1) ,"") | G1081: =IF(C1081 <> "", IF(DAY(A1080) = DAY(A1081), G1080+1, 1) ,"") | H1081: =IF(C1081 <> "", IF(MONTH(A1080) = MONTH(A1081), H1080+1, 1) ,"") | I1081: =IF(C1081 <> "", IF(YEAR(A1080) = YEAR(A1081), I1080+1, 1) ,"")
C1082: =IFERROR(VLOOKUP(B1082,'Overall Bean Summary'!A$2:B$36,2,FALSE),"") | D1082: =IF(A1082 <> "", IF(C1082 = "Spicy", D1081, IF(C1082 = "Good", D1081+1, 0)), "") | E1082: =IF(A1082 <> "", IF(C1082 = "Spicy", E1081, IF(C1082 = "Bad", E1081+1 , 0)), "") | F1082: =IF(B1082 <> "", if(B1082 = B1081, F1081+1, 1) ,"") | G1082: =IF(C1082 <> "", IF(DAY(A1081) = DAY(A1082), G1081+1, 1) ,"") | H1082: =IF(C1082 <> "", IF(MONTH(A1081) = MONTH(A1082), H1081+1, 1) ,"") | I1082: =IF(C1082 <> "", IF(YEAR(A1081) = YEAR(A1082), I1081+1, 1) ,"")
C1083: =IFERROR(VLOOKUP(B1083,'Overall Bean Summary'!A$2:B$36,2,FALSE),"") | D1083: =IF(A1083 <> "", IF(C1083 = "Spicy", D1082, IF(C1083 = "Good", D1082+1, 0)), "") | E1083: =IF(A1083 <> "", IF(C1083 = "Spicy", E1082, IF(C1083 = "Bad", E1082+1 , 0)), "") | F1083: =IF(B1083 <> "", if(B1083 = B1082, F1082+1, 1) ,"") | G1083: =IF(C1083 <> "", IF(DAY(A1082) = DAY(A1083), G1082+1, 1) ,"") | H1083: =IF(C1083 <> "", IF(MONTH(A1082) = MONTH(A1083), H1082+1, 1) ,"") | I1083: =IF(C1083 <> "", IF(YEAR(A1082) = YEAR(A1083), I1082+1, 1) ,"")
C1084: =IFERROR(VLOOKUP(B1084,'Overall Bean Summary'!A$2:B$36,2,FALSE),"") | D1084: =IF(A1084 <> "", IF(C1084 = "Spicy", D1083, IF(C1084 = "Good", D1083+1, 0)), "") | E1084: =IF(A1084 <> "", IF(C1084 = "Spicy", E1083, IF(C1084 = "Bad", E1083+1 , 0)), "") | F1084: =IF(B1084 <> "", if(B1084 = B1083, F1083+1, 1) ,"") | G1084: =IF(C1084 <> "", IF(DAY(A1083) = DAY(A1084), G1083+1, 1) ,"") | H1084: =IF(C1084 <> "", IF(MONTH(A1083) = MONTH(A1084), H1083+1, 1) ,"") | I1084: =IF(C1084 <> "", IF(YEAR(A1083) = YEAR(A1084), I1083+1, 1) ,"")
C1085: =IFERROR(VLOOKUP(B1085,'Overall Bean Summary'!A$2:B$36,2,FALSE),"") | D1085: =IF(A1085 <> "", IF(C1085 = "Spicy", D1084, IF(C1085 = "Good", D1084+1, 0)), "") | E1085: =IF(A1085 <> "", IF(C1085 = "Spicy", E1084, IF(C1085 = "Bad", E1084+1 , 0)), "") | F1085: =IF(B1085 <> "", if(B1085 = B1084, F1084+1, 1) ,"") | G1085: =IF(C1085 <> "", IF(DAY(A1084) = DAY(A1085), G1084+1, 1) ,"") | H1085: =IF(C1085 <> "", IF(MONTH(A1084) = MONTH(A1085), H1084+1, 1) ,"") | I1085: =IF(C1085 <> "", IF(YEAR(A1084) = YEAR(A1085), I1084+1, 1) ,"")
C1086: =IFERROR(VLOOKUP(B1086,'Overall Bean Summary'!A$2:B$36,2,FALSE),"") | D1086: =IF(A1086 <> "", IF(C1086 = "Spicy", D1085, IF(C1086 = "Good", D1085+1, 0)), "") | E1086: =IF(A1086 <> "", IF(C1086 = "Spicy", E1085, IF(C1086 = "Bad", E1085+1 , 0)), "") | F1086: =IF(B1086 <> "", if(B1086 = B1085, F1085+1, 1) ,"") | G1086: =IF(C1086 <> "", IF(DAY(A1085) = DAY(A1086), G1085+1, 1) ,"") | H1086: =IF(C1086 <> "", IF(MONTH(A1085) = MONTH(A1086), H1085+1, 1) ,"") | I1086: =IF(C1086 <> "", IF(YEAR(A1085) = YEAR(A1086), I1085+1, 1) ,"")
... C1096: =IFERROR(VLOOKUP(B1096,'Overall Bean Summary'!A$2:B$36,2,FALSE),"") | D1096: =IF(A1096 <> "", IF(C1096 = "Spicy", D1095, IF(C1096 = "Good", D1095+1, 0)), "") | E1096: =IF(A1096 <> "", IF(C1096 = "Spicy", E1095, IF(C1096 = "Bad", E1095+1 , 0)), "") | F1096: =IF(B1096 <> "", if(B1096 = B1095, F1095+1, 1) ,"") | G1096: =IF(C1096 <> "", IF(DAY(A1095) = DAY(A1096), G1095+1, 1) ,"") | H1096: =IF(C1096 <> "", IF(MONTH(A1095) = MONTH(A1096), H1095+1, 1) ,"") | I1096: =IF(C1096 <> "", IF(YEAR(A1095) = YEAR(A1096), I1095+1, 1) ,"")
C1097: =IFERROR(VLOOKUP(B1097,'Overall Bean Summary'!A$2:B$36,2,FALSE),"")
C1098: =IFERROR(VLOOKUP(B1098,'Overall Bean Summary'!A$2:B$36,2,FALSE),"")
C1099: =IFERROR(VLOOKUP(B1099,'Overall Bean Summary'!A$2:B$36,2,FALSE),"")
C1100: =IFERROR(VLOOKUP(B1100,'Overall Bean Summary'!A$2:B$36,2,FALSE),"")
C1101: =IFERROR(VLOOKUP(B1101,'Overall Bean Summary'!A$2:B$36,2,FALSE),"")

Sheet Graphs
A1: Date | B1: Count | C1: Good | D1: Bad | E1: Spicy | G1: Beans | H1: # Streams
A2: =Beans!A2 -> 44852 | B2: =if(A2<>"", COUNTIFS(Beans!A:A, A2), "") -> 1 | C2: =if(A2<>"", COUNTIFS(Beans!A:A, A2, Beans!C:C, "Good" ), "") -> 0 | D2: =if(A2<>"", COUNTIFS(Beans!A:A, A2, Beans!C:C, "Bad" ), "") -> 1 | E2: =if(A2<>"", COUNTIFS(Beans!A:A, A2, Beans!C:C, "Spicy" ), "") -> 0 | G2: 1 | H2: =COUNTIFS(B:B, G2) -> 200
A3: =IF(A2>=TODAY(), "", A2+1) -> 44853 | B3: =if(A3<>"", COUNTIFS(Beans!A:A, A3), "") -> 1 | C3: =if(A3<>"", COUNTIFS(Beans!A:A, A3, Beans!C:C, "Good" ), "") -> 1 | D3: =if(A3<>"", COUNTIFS(Beans!A:A, A3, Beans!C:C, "Bad" ), "") -> 0 | E3: =if(A3<>"", COUNTIFS(Beans!A:A, A3, Beans!C:C, "Spicy" ), "") -> 0 | G3: 2 | H3: =COUNTIFS(B:B, G3) -> 91
A4: =IF(A3>=TODAY(), "", A3+1) -> 44854 | B4: =if(A4<>"", COUNTIFS(Beans!A:A, A4), "") -> 1 | C4: =if(A4<>"", COUNTIFS(Beans!A:A, A4, Beans!C:C, "Good" ), "") -> 0 | D4: =if(A4<>"", COUNTIFS(Beans!A:A, A4, Beans!C:C, "Bad" ), "") -> 1 | E4: =if(A4<>"", COUNTIFS(Beans!A:A, A4, Beans!C:C, "Spicy" ), "") -> 0 | G4: 3 | H4: =COUNTIFS(B:B, G4) -> 60
A5: =IF(A4>=TODAY(), "", A4+1) -> 44855 | B5: =if(A5<>"", COUNTIFS(Beans!A:A, A5), "") -> 1 | C5: =if(A5<>"", COUNTIFS(Beans!A:A, A5, Beans!C:C, "Good" ), "") -> 1 | D5: =if(A5<>"", COUNTIFS(Beans!A:A, A5, Beans!C:C, "Bad" ), "") -> 0 | E5: =if(A5<>"", COUNTIFS(Beans!A:A, A5, Beans!C:C, "Spicy" ), "") -> 0 | G5: 4 | H5: =COUNTIFS(B:B, G5) -> 28
A6: =IF(A5>=TODAY(), "", A5+1) -> 44856 | B6: =if(A6<>"", COUNTIFS(Beans!A:A, A6), "") -> 0 | C6: =if(A6<>"", COUNTIFS(Beans!A:A, A6, Beans!C:C, "Good" ), "") -> 0 | D6: =if(A6<>"", COUNTIFS(Beans!A:A, A6, Beans!C:C, "Bad" ), "") -> 0 | E6: =if(A6<>"", COUNTIFS(Beans!A:A, A6, Beans!C:C, "Spicy" ), "") -> 0 | G6: 5 | H6: =COUNTIFS(B:B, G6) -> 10
A7: =IF(A6>=TODAY(), "", A6+1) -> 44857 | B7: =if(A7<>"", COUNTIFS(Beans!A:A, A7), "") -> 0 | C7: =if(A7<>"", COUNTIFS(Beans!A:A, A7, Beans!C:C, "Good" ), "") -> 0 | D7: =if(A7<>"", COUNTIFS(Beans!A:A, A7, Beans!C:C, "Bad" ), "") -> 0 | E7: =if(A7<>"", COUNTIFS(Beans!A:A, A7, Beans!C:C, "Spicy" ), "") -> 0 | G7: 6 | H7: =COUNTIFS(B:B, G7) -> 13
A8: =IF(A7>=TODAY(), "", A7+1) -> 44858 | B8: =if(A8<>"", COUNTIFS(Beans!A:A, A8), "") -> 1 | C8: =if(A8<>"", COUNTIFS(Beans!A:A, A8, Beans!C:C, "Good" ), "") -> 0 | D8: =if(A8<>"", COUNTIFS(Beans!A:A, A8, Beans!C:C, "Bad" ), "") -> 1 | E8: =if(A8<>"", COUNTIFS(Beans!A:A, A8, Beans!C:C, "Spicy" ), "") -> 0 | G8: 7 | H8: =COUNTIFS(B:B, G8) -> 5
A9: =IF(A8>=TODAY(), "", A8+1) -> 44859 | B9: =if(A9<>"", COUNTIFS(Beans!A:A, A9), "") -> 1 | C9: =if(A9<>"", COUNTIFS(Beans!A:A, A9, Beans!C:C, "Good" ), "") -> 0 | D9: =if(A9<>"", COUNTIFS(Beans!A:A, A9, Beans!C:C, "Bad" ), "") -> 1 | E9: =if(A9<>"", COUNTIFS(Beans!A:A, A9, Beans!C:C, "Spicy" ), "") -> 0 | G9: 8 | H9: =COUNTIFS(B:B, G9) -> 6
A10: =IF(A9>=TODAY(), "", A9+1) -> 44860 | B10: =if(A10<>"", COUNTIFS(Beans!A:A, A10), "") -> 1 | C10: =if(A10<>"", COUNTIFS(Beans!A:A, A10, Beans!C:C, "Good" ), "") -> 1 | D10: =if(A10<>"", COUNTIFS(Beans!A:A, A10, Beans!C:C, "Bad" ), "") -> 0 | E10: =if(A10<>"", COUNTIFS(Beans!A:A, A10, Beans!C:C, "Spicy" ), "") -> 0 | G10: 9 | H10: =COUNTIFS(B:B, G10) -> 4
A11: =IF(A10>=TODAY(), "", A10+1) -> 44861 | B11: =if(A11<>"", COUNTIFS(Beans!A:A, A11), "") -> 1 | C11: =if(A11<>"", COUNTIFS(Beans!A:A, A11, Beans!C:C, "Good" ), "") -> 1 | D11: =if(A11<>"", COUNTIFS(Beans!A:A, A11, Beans!C:C, "Bad" ), "") -> 0 | E11: =if(A11<>"", COUNTIFS(Beans!A:A, A11, Beans!C:C, "Spicy" ), "") -> 0 | G11: 10 | H11: =COUNTIFS(B:B, G11) -> 2
A12: =IF(A11>=TODAY(), "", A11+1) -> 44862 | B12: =if(A12<>"", COUNTIFS(Beans!A:A, A12), "") -> 1 | C12: =if(A12<>"", COUNTIFS(Beans!A:A, A12, Beans!C:C, "Good" ), "") -> 0 | D12: =if(A12<>"", COUNTIFS(Beans!A:A, A12, Beans!C:C, "Bad" ), "") -> 1 | E12: =if(A12<>"", COUNTIFS(Beans!A:A, A12, Beans!C:C, "Spicy" ), "") -> 0 | G12: 11 | H12: =COUNTIFS(B:B, G12) -> 0
A13: =IF(A12>=TODAY(), "", A12+1) -> 44863 | B13: =if(A13<>"", COUNTIFS(Beans!A:A, A13), "") -> 0 | C13: =if(A13<>"", COUNTIFS(Beans!A:A, A13, Beans!C:C, "Good" ), "") -> 0 | D13: =if(A13<>"", COUNTIFS(Beans!A:A, A13, Beans!C:C, "Bad" ), "") -> 0 | E13: =if(A13<>"", COUNTIFS(Beans!A:A, A13, Beans!C:C, "Spicy" ), "") -> 0 | G13: 12 | H13: =COUNTIFS(B:B, G13) -> 0
A14: =IF(A13>=TODAY(), "", A13+1) -> 44864 | B14: =if(A14<>"", COUNTIFS(Beans!A:A, A14), "") -> 0 | C14: =if(A14<>"", COUNTIFS(Beans!A:A, A14, Beans!C:C, "Good" ), "") -> 0 | D14: =if(A14<>"", COUNTIFS(Beans!A:A, A14, Beans!C:C, "Bad" ), "") -> 0 | E14: =if(A14<>"", COUNTIFS(Beans!A:A, A14, Beans!C:C, "Spicy" ), "") -> 0 | G14: 13 | H14: =COUNTIFS(B:B, G14) -> 1
... A26: =IF(A25>=TODAY(), "", A25+1) -> 44876 | B26: =if(A26<>"", COUNTIFS(Beans!A:A, A26), "") -> 1 | C26: =if(A26<>"", COUNTIFS(Beans!A:A, A26, Beans!C:C, "Good" ), "") -> 0 | D26: =if(A26<>"", COUNTIFS(Beans!A:A, A26, Beans!C:C, "Bad" ), "") -> 1 | E26: =if(A26<>"", COUNTIFS(Beans!A:A, A26, Beans!C:C, "Spicy" ), "") -> 0 | G26: 25 | H26: =COUNTIFS(B:B, G26) -> 0
A27: =IF(A26>=TODAY(), "", A26+1) -> 44877 | B27: =if(A27<>"", COUNTIFS(Beans!A:A, A27), "") -> 0 | C27: =if(A27<>"", COUNTIFS(Beans!A:A, A27, Beans!C:C, "Good" ), "") -> 0 | D27: =if(A27<>"", COUNTIFS(Beans!A:A, A27, Beans!C:C, "Bad" ), "") -> 0 | E27: =if(A27<>"", COUNTIFS(Beans!A:A, A27, Beans!C:C, "Spicy" ), "") -> 0 | G27: =G26+1 -> 26 | H27: =COUNTIFS(B:B, G27) -> 0
A28: =IF(A27>=TODAY(), "", A27+1) -> 44878 | B28: =if(A28<>"", COUNTIFS(Beans!A:A, A28), "") -> 0 | C28: =if(A28<>"", COUNTIFS(Beans!A:A, A28, Beans!C:C, "Good" ), "") -> 0 | D28: =if(A28<>"", COUNTIFS(Beans!A:A, A28, Beans!C:C, "Bad" ), "") -> 0 | E28: =if(A28<>"", COUNTIFS(Beans!A:A, A28, Beans!C:C, "Spicy" ), "") -> 0 | G28: =G27+1 -> 27 | H28: =COUNTIFS(B:B, G28) -> 0
A29: =IF(A28>=TODAY(), "", A28+1) -> 44879 | B29: =if(A29<>"", COUNTIFS(Beans!A:A, A29), "") -> 1 | C29: =if(A29<>"", COUNTIFS(Beans!A:A, A29, Beans!C:C, "Good" ), "") -> 1 | D29: =if(A29<>"", COUNTIFS(Beans!A:A, A29, Beans!C:C, "Bad" ), "") -> 0 | E29: =if(A29<>"", COUNTIFS(Beans!A:A, A29, Beans!C:C, "Spicy" ), "") -> 0 | G29: =G28+1 -> 28 | H29: =COUNTIFS(B:B, G29) -> 0
A30: =IF(A29>=TODAY(), "", A29+1) -> 44880 | B30: =if(A30<>"", COUNTIFS(Beans!A:A, A30), "") -> 1 | C30: =if(A30<>"", COUNTIFS(Beans!A:A, A30, Beans!C:C, "Good" ), "") -> 0 | D30: =if(A30<>"", COUNTIFS(Beans!A:A, A30, Beans!C:C, "Bad" ), "") -> 1 | E30: =if(A30<>"", COUNTIFS(Beans!A:A, A30, Beans!C:C, "Spicy" ), "") -> 0 | G30: =G29+1 -> 29 | H30: =COUNTIFS(B:B, G30) -> 0
A31: =IF(A30>=TODAY(), "", A30+1) -> 44881 | B31: =if(A31<>"", COUNTIFS(Beans!A:A, A31), "") -> 1 | C31: =if(A31<>"", COUNTIFS(Beans!A:A, A31, Beans!C:C, "Good" ), "") -> 1 | D31: =if(A31<>"", COUNTIFS(Beans!A:A, A31, Beans!C:C, "Bad" ), "") -> 0 | E31: =if(A31<>"", COUNTIFS(Beans!A:A, A31, Beans!C:C, "Spicy" ), "") -> 0 | G31: =G30+1 -> 30 | H31: =COUNTIFS(B:B, G31) -> 0
A32: =IF(A31>=TODAY(), "", A31+1) -> 44882 | B32: =if(A32<>"", COUNTIFS(Beans!A:A, A32), "") -> 2 | C32: =if(A32<>"", COUNTIFS(Beans!A:A, A32, Beans!C:C, "Good" ), "") -> 1 | D32: =if(A32<>"", COUNTIFS(Beans!A:A, A32, Beans!C:C, "Bad" ), "") -> 1 | E32: =if(A32<>"", COUNTIFS(Beans!A:A, A32, Beans!C:C, "Spicy" ), "") -> 0 | G32: =G31+1 -> 31 | H32: =COUNTIFS(B:B, G32) -> 0
A33: =IF(A32>=TODAY(), "", A32+1) -> 44883 | B33: =if(A33<>"", COUNTIFS(Beans!A:A, A33), "") -> 1 | C33: =if(A33<>"", COUNTIFS(Beans!A:A, A33, Beans!C:C, "Good" ), "") -> 0 | D33: =if(A33<>"", COUNTIFS(Beans!A:A, A33, Beans!C:C, "Bad" ), "") -> 1 | E33: =if(A33<>"", COUNTIFS(Beans!A:A, A33, Beans!C:C, "Spicy" ), "") -> 0 | G33: =G32+1 -> 32 | H33: =COUNTIFS(B:B, G33) -> 0
A34: =IF(A33>=TODAY(), "", A33+1) -> 44884 | B34: =if(A34<>"", COUNTIFS(Beans!A:A, A34), "") -> 0 | C34: =if(A34<>"", COUNTIFS(Beans!A:A, A34, Beans!C:C, "Good" ), "") -> 0 | D34: =if(A34<>"", COUNTIFS(Beans!A:A, A34, Beans!C:C, "Bad" ), "") -> 0 | E34: =if(A34<>"", COUNTIFS(Beans!A:A, A34, Beans!C:C, "Spicy" ), "") -> 0 | G34: =G33+1 -> 33 | H34: =COUNTIFS(B:B, G34) -> 1
A35: =IF(A34>=TODAY(), "", A34+1) -> 44885 | B35: =if(A35<>"", COUNTIFS(Beans!A:A, A35), "") -> 0 | C35: =if(A35<>"", COUNTIFS(Beans!A:A, A35, Beans!C:C, "Good" ), "") -> 0 | D35: =if(A35<>"", COUNTIFS(Beans!A:A, A35, Beans!C:C, "Bad" ), "") -> 0 | E35: =if(A35<>"", COUNTIFS(Beans!A:A, A35, Beans!C:C, "Spicy" ), "") -> 0 | G35: =G34+1 -> 34 | H35: =COUNTIFS(B:B, G35) -> 0
A36: =IF(A35>=TODAY(), "", A35+1) -> 44886 | B36: =if(A36<>"", COUNTIFS(Beans!A:A, A36), "") -> 1 | C36: =if(A36<>"", COUNTIFS(Beans!A:A, A36, Beans!C:C, "Good" ), "") -> 0 | D36: =if(A36<>"", COUNTIFS(Beans!A:A, A36, Beans!C:C, "Bad" ), "") -> 1 | E36: =if(A36<>"", COUNTIFS(Beans!A:A, A36, Beans!C:C, "Spicy" ), "") -> 0 | H36: =SUM(H2:H35) -> 426 | I36: ='Overall Bean Summary'!N7-H36 -> 787
A37: =IF(A36>=TODAY(), "", A36+1) -> 44887 | B37: =if(A37<>"", COUNTIFS(Beans!A:A, A37), "") -> 1 | C37: =if(A37<>"", COUNTIFS(Beans!A:A, A37, Beans!C:C, "Good" ), "") -> 0 | D37: =if(A37<>"", COUNTIFS(Beans!A:A, A37, Beans!C:C, "Bad" ), "") -> 1 | E37: =if(A37<>"", COUNTIFS(Beans!A:A, A37, Beans!C:C, "Spicy" ), "") -> 0
A38: =IF(A37>=TODAY(), "", A37+1) -> 44888 | B38: =if(A38<>"", COUNTIFS(Beans!A:A, A38), "") -> 1 | C38: =if(A38<>"", COUNTIFS(Beans!A:A, A38, Beans!C:C, "Good" ), "") -> 0 | D38: =if(A38<>"", COUNTIFS(Beans!A:A, A38, Beans!C:C, "Bad" ), "") -> 1 | E38: =if(A38<>"", COUNTIFS(Beans!A:A, A38, Beans!C:C, "Spicy" ), "") -> 0
A39: =IF(A38>=TODAY(), "", A38+1) -> 44889 | B39: =if(A39<>"", COUNTIFS(Beans!A:A, A39), "") -> 1 | C39: =if(A39<>"", COUNTIFS(Beans!A:A, A39, Beans!C:C, "Good" ), "") -> 0 | D39: =if(A39<>"", COUNTIFS(Beans!A:A, A39, Beans!C:C, "Bad" ), "") -> 1 | E39: =if(A39<>"", COUNTIFS(Beans!A:A, A39, Beans!C:C, "Spicy" ), "") -> 0
A40: =IF(A39>=TODAY(), "", A39+1) -> 44890 | B40: =if(A40<>"", COUNTIFS(Beans!A:A, A40), "") -> 2 | C40: =if(A40<>"", COUNTIFS(Beans!A:A, A40, Beans!C:C, "Good" ), "") -> 0 | D40: =if(A40<>"", COUNTIFS(Beans!A:A, A40, Beans!C:C, "Bad" ), "") -> 2 | E40: =if(A40<>"", COUNTIFS(Beans!A:A, A40, Beans!C:C, "Spicy" ), "") -> 0
A41: =IF(A40>=TODAY(), "", A40+1) -> 44891 | B41: =if(A41<>"", COUNTIFS(Beans!A:A, A41), "") -> 0 | C41: =if(A41<>"", COUNTIFS(Beans!A:A, A41, Beans!C:C, "Good" ), "") -> 0 | D41: =if(A41<>"", COUNTIFS(Beans!A:A, A41, Beans!C:C, "Bad" ), "") -> 0 | E41: =if(A41<>"", COUNTIFS(Beans!A:A, A41, Beans!C:C, "Spicy" ), "") -> 0
A42: =IF(A41>=TODAY(), "", A41+1) -> 44892 | B42: =if(A42<>"", COUNTIFS(Beans!A:A, A42), "") -> 0 | C42: =if(A42<>"", COUNTIFS(Beans!A:A, A42, Beans!C:C, "Good" ), "") -> 0 | D42: =if(A42<>"", COUNTIFS(Beans!A:A, A42, Beans!C:C, "Bad" ), "") -> 0 | E42: =if(A42<>"", COUNTIFS(Beans!A:A, A42, Beans!C:C, "Spicy" ), "") -> 0
A43: =IF(A42>=TODAY(), "", A42+1) -> 44893 | B43: =if(A43<>"", COUNTIFS(Beans!A:A, A43), "") -> 1 | C43: =if(A43<>"", COUNTIFS(Beans!A:A, A43, Beans!C:C, "Good" ), "") -> 0 | D43: =if(A43<>"", COUNTIFS(Beans!A:A, A43, Beans!C:C, "Bad" ), "") -> 1 | E43: =if(A43<>"", COUNTIFS(Beans!A:A, A43, Beans!C:C, "Spicy" ), "") -> 0
A44: =IF(A43>=TODAY(), "", A43+1) -> 44894 | B44: =if(A44<>"", COUNTIFS(Beans!A:A, A44), "") -> 1 | C44: =if(A44<>"", COUNTIFS(Beans!A:A, A44, Beans!C:C, "Good" ), "") -> 0 | D44: =if(A44<>"", COUNTIFS(Beans!A:A, A44, Beans!C:C, "Bad" ), "") -> 1 | E44: =if(A44<>"", COUNTIFS(Beans!A:A, A44, Beans!C:C, "Spicy" ), "") -> 0
A45: =IF(A44>=TODAY(), "", A44+1) -> 44895 | B45: =if(A45<>"", COUNTIFS(Beans!A:A, A45), "") -> 0 | C45: =if(A45<>"", COUNTIFS(Beans!A:A, A45, Beans!C:C, "Good" ), "") -> 0 | D45: =if(A45<>"", COUNTIFS(Beans!A:A, A45, Beans!C:C, "Bad" ), "") -> 0 | E45: =if(A45<>"", COUNTIFS(Beans!A:A, A45, Beans!C:C, "Spicy" ), "") -> 0
A46: =IF(A45>=TODAY(), "", A45+1) -> 44896 | B46: =if(A46<>"", COUNTIFS(Beans!A:A, A46), "") -> 1 | C46: =if(A46<>"", COUNTIFS(Beans!A:A, A46, Beans!C:C, "Good" ), "") -> 1 | D46: =if(A46<>"", COUNTIFS(Beans!A:A, A46, Beans!C:C, "Bad" ), "") -> 0 | E46: =if(A46<>"", COUNTIFS(Beans!A:A, A46, Beans!C:C, "Spicy" ), "") -> 0
A47: =IF(A46>=TODAY(), "", A46+1) -> 44897 | B47: =if(A47<>"", COUNTIFS(Beans!A:A, A47), "") -> 2 | C47: =if(A47<>"", COUNTIFS(Beans!A:A, A47, Beans!C:C, "Good" ), "") -> 1 | D47: =if(A47<>"", COUNTIFS(Beans!A:A, A47, Beans!C:C, "Bad" ), "") -> 1 | E47: =if(A47<>"", COUNTIFS(Beans!A:A, A47, Beans!C:C, "Spicy" ), "") -> 0
A48: =IF(A47>=TODAY(), "", A47+1) -> 44898 | B48: =if(A48<>"", COUNTIFS(Beans!A:A, A48), "") -> 0 | C48: =if(A48<>"", COUNTIFS(Beans!A:A, A48, Beans!C:C, "Good" ), "") -> 0 | D48: =if(A48<>"", COUNTIFS(Beans!A:A, A48, Beans!C:C, "Bad" ), "") -> 0 | E48: =if(A48<>"", COUNTIFS(Beans!A:A, A48, Beans!C:C, "Spicy" ), "") -> 0
... A1000: =IF(A999>=TODAY(), "", A999+1) -> 45850 | B1000: =if(A1000<>"", COUNTIFS(Beans!A:A, A1000), "") -> 0 | C1000: =if(A1000<>"", COUNTIFS(Beans!A:A, A1000, Beans!C:C, "Good" ), "") -> 0 | D1000: =if(A1000<>"", COUNTIFS(Beans!A:A, A1000, Beans!C:C, "Bad" ), "") -> 0 | E1000: =if(A1000<>"", COUNTIFS(Beans!A:A, A1000, Beans!C:C, "Spicy" ), "") -> 0

Sheet 2026 Bean Description
A1: Flavor | B1: Good/Bad | C1: Seasons | D1: Bean | E1: Total | F1: % | G1: January | H1: February | I1: March | J1: April | K1: May | L1: June | M1: July | N1: August | O1: September | P1: October | Q1: November | R1: December
A2: Juicy Pear | B2: Good | C2: 1st-Curr | D2: =D3 | E2: =SUM(G2:R2) -> 1 | F2: =IF(E2+E3 = 0, "n/a", E2/(E2+E3)) -> 0.071428571 | G2: =COUNTIFS(Beans!B:B, A2, Beans!A:A, ">=2026-1-1", Beans!A:A,"<2026-2-1" ) -> 0 | H2: =COUNTIFS(Beans!B:B, A2, Beans!A:A, ">=2026-2-1", Beans!A:A,"<2026-3-1" ) -> 0 | I2: =COUNTIFS(Beans!B:B, A2, Beans!A:A, ">=2026-3-1", Beans!A:A,"<2026-4-1" ) -> 0 | J2: =COUNTIFS(Beans!B:B, A2, Beans!A:A, ">=2026-4-1", Beans!A:A,"<2026-5-1" ) -> 1 | K2: =COUNTIFS(Beans!B:B, A2, Beans!A:A, ">=2026-5-1", Beans!A:A,"<2026-6-1" ) -> 0 | L2: =COUNTIFS(Beans!B:B, A2, Beans!A:A, ">=2026-6-1", Beans!A:A,"<2026-7-1" ) -> 0 | M2: =COUNTIFS(Beans!B:B, A2, Beans!A:A, ">=2026-7-1", Beans!A:A,"<2026-8-1" ) -> 0 | N2: =COUNTIFS(Beans!B:B, A2, Beans!A:A, ">=2026-8-1", Beans!A:A,"<2026-9-1" ) -> 0 | O2: =COUNTIFS(Beans!B:B, A2, Beans!A:A, ">=2026-9-1", Beans!A:A,"<2026-10-1" ) -> 0 | P2: =COUNTIFS(Beans!B:B, A2, Beans!A:A, ">=2026-10-1", Beans!A:A,"<2026-11-1" ) -> 0 | Q2: =COUNTIFS(Beans!B:B, A2, Beans!A:A, ">=2026-11-1", Beans!A:A,"<2026-12-1" ) -> 0 | R2: =COUNTIFS(Beans!B:B, A2, Beans!A:A, ">=2026-12-1", Beans!A:A,"<2027-1-1" ) -> 0
A3: Booger | B3: Bad | C3: 1st-Curr | E3: =SUM(G3:R3) -> 13 | F3: =IF(E2+E3 = 0, "n/a", E3/(E2+E3)) -> 0.92857143 | G3: =COUNTIFS(Beans!B:B, A3, Beans!A:A, ">=2026-1-1", Beans!A:A,"<2026-2-1" ) -> 3 | H3: =COUNTIFS(Beans!B:B, A3, Beans!A:A, ">=2026-2-1", Beans!A:A,"<2026-3-1" ) -> 1 | I3: =COUNTIFS(Beans!B:B, A3, Beans!A:A, ">=2026-3-1", Beans!A:A,"<2026-4-1" ) -> 0 | J3: =COUNTIFS(Beans!B:B, A3, Beans!A:A, ">=2026-4-1", Beans!A:A,"<2026-5-1" ) -> 0 | K3: =COUNTIFS(Beans!B:B, A3, Beans!A:A, ">=2026-5-1", Beans!A:A,"<2026-6-1" ) -> 3 | L3: =COUNTIFS(Beans!B:B, A3, Beans!A:A, ">=2026-6-1", Beans!A:A,"<2026-7-1" ) -> 0 | M3: =COUNTIFS(Beans!B:B, A3, Beans!A:A, ">=2026-7-1", Beans!A:A,"<2026-8-1" ) -> 0 | N3: =COUNTIFS(Beans!B:B, A3, Beans!A:A, ">=2026-8-1", Beans!A:A,"<2026-9-1" ) -> 1 | O3: =COUNTIFS(Beans!B:B, A3, Beans!A:A, ">=2026-9-1", Beans!A:A,"<2026-10-1" ) -> 5 | P3: =COUNTIFS(Beans!B:B, A3, Beans!A:A, ">=2026-10-1", Beans!A:A,"<2026-11-1" ) -> 0 | Q3: =COUNTIFS(Beans!B:B, A3, Beans!A:A, ">=2026-11-1", Beans!A:A,"<2026-12-1" ) -> 0 | R3: =COUNTIFS(Beans!B:B, A3, Beans!A:A, ">=2026-12-1", Beans!A:A,"<2027-1-1" ) -> 0
A4: Strawberry Smoothie | B4: Good | C4: 4th-Curr | D4: =D5 | E4: =SUM(G4:R4) -> 8 | F4: =IF(E4+E5 = 0, "n/a", E4/(E4+E5)) -> 0.72727273 | G4: =COUNTIFS(Beans!B:B, A4, Beans!A:A, ">=2026-1-1", Beans!A:A,"<2026-2-1" ) -> 0 | H4: =COUNTIFS(Beans!B:B, A4, Beans!A:A, ">=2026-2-1", Beans!A:A,"<2026-3-1" ) -> 0 | I4: =COUNTIFS(Beans!B:B, A4, Beans!A:A, ">=2026-3-1", Beans!A:A,"<2026-4-1" ) -> 1 | J4: =COUNTIFS(Beans!B:B, A4, Beans!A:A, ">=2026-4-1", Beans!A:A,"<2026-5-1" ) -> 0 | K4: =COUNTIFS(Beans!B:B, A4, Beans!A:A, ">=2026-5-1", Beans!A:A,"<2026-6-1" ) -> 0 | L4: =COUNTIFS(Beans!B:B, A4, Beans!A:A, ">=2026-6-1", Beans!A:A,"<2026-7-1" ) -> 1 | M4: =COUNTIFS(Beans!B:B, A4, Beans!A:A, ">=2026-7-1", Beans!A:A,"<2026-8-1" ) -> 0 | N4: =COUNTIFS(Beans!B:B, A4, Beans!A:A, ">=2026-8-1", Beans!A:A,"<2026-9-1" ) -> 2 | O4: =COUNTIFS(Beans!B:B, A4, Beans!A:A, ">=2026-9-1", Beans!A:A,"<2026-10-1" ) -> 4 | P4: =COUNTIFS(Beans!B:B, A4, Beans!A:A, ">=2026-10-1", Beans!A:A,"<2026-11-1" ) -> 0 | Q4: =COUNTIFS(Beans!B:B, A4, Beans!A:A, ">=2026-11-1", Beans!A:A,"<2026-12-1" ) -> 0 | R4: =COUNTIFS(Beans!B:B, A4, Beans!A:A, ">=2026-12-1", Beans!A:A,"<2027-1-1" ) -> 0
A5: Dead Fish (Rotten) | B5: Bad | C5: 4th-Curr | E5: =SUM(G5:R5) -> 3 | F5: =IF(E4+E5 = 0, "n/a", E5/(E4+E5)) -> 0.27272727 | G5: =COUNTIFS(Beans!B:B, A5, Beans!A:A, ">=2026-1-1", Beans!A:A,"<2026-2-1" ) -> 0 | H5: =COUNTIFS(Beans!B:B, A5, Beans!A:A, ">=2026-2-1", Beans!A:A,"<2026-3-1" ) -> 0 | I5: =COUNTIFS(Beans!B:B, A5, Beans!A:A, ">=2026-3-1", Beans!A:A,"<2026-4-1" ) -> 0 | J5: =COUNTIFS(Beans!B:B, A5, Beans!A:A, ">=2026-4-1", Beans!A:A,"<2026-5-1" ) -> 0 | K5: =COUNTIFS(Beans!B:B, A5, Beans!A:A, ">=2026-5-1", Beans!A:A,"<2026-6-1" ) -> 0 | L5: =COUNTIFS(Beans!B:B, A5, Beans!A:A, ">=2026-6-1", Beans!A:A,"<2026-7-1" ) -> 0 | M5: =COUNTIFS(Beans!B:B, A5, Beans!A:A, ">=2026-7-1", Beans!A:A,"<2026-8-1" ) -> 0 | N5: =COUNTIFS(Beans!B:B, A5, Beans!A:A, ">=2026-8-1", Beans!A:A,"<2026-9-1" ) -> 0 | O5: =COUNTIFS(Beans!B:B, A5, Beans!A:A, ">=2026-9-1", Beans!A:A,"<2026-10-1" ) -> 3 | P5: =COUNTIFS(Beans!B:B, A5, Beans!A:A, ">=2026-10-1", Beans!A:A,"<2026-11-1" ) -> 0 | Q5: =COUNTIFS(Beans!B:B, A5, Beans!A:A, ">=2026-11-1", Beans!A:A,"<2026-12-1" ) -> 0 | R5: =COUNTIFS(Beans!B:B, A5, Beans!A:A, ">=2026-12-1", Beans!A:A,"<2027-1-1" ) -> 0
